Workbook

Sheet 人员数据源
A1: city_name | B1: org_name | C1: real_name | D1: sale_oa | E1: onboard_time | F1: 当日呼出电话数 | G1: 当日接通电话数 | H1: 当日接通率 | I1: 当日30s电话数 | J1: 当日45s电话数 | K1: 当日60s电话数 | L1: 当日180s电话数 | M1: 当日累计接通时长(分钟) | N1: 当日外访客户数 | O1: 当日外访签单客户数 | P1: 当日外访签单率 | Q1: 当日总外访时长（分钟） | R1: (辅助)是否计算 | S1: 辅助（司龄） | T1: 主管 | U1: 提报意向数
A2: 青岛 | B2: 增值一部 | C2: 李雪 | D2: lixue51 | E2: 2023-08-25 | F2: =IFERROR(VLOOKUP(C2,路飞话务数据源!D:Q,2,FALSE),0) -> 8 | G2: =IFERROR(VLOOKUP(C2,路飞话务数据源!D:Q,3,FALSE),0) -> 6 | H2: =IFERROR(VLOOKUP(C2,路飞话务数据源!D:Q,4,FALSE),0) -> 0.75 | I2: =IFERROR(VLOOKUP(C2,路飞话务数据源!D:Q,5,FALSE),0) -> 5 | J2: =IFERROR(VLOOKUP(C2,路飞话务数据源!D:Q,6,FALSE),0) -> 5 | K2: =IFERROR(VLOOKUP(C2,路飞话务数据源!D:Q,7,FALSE),0) -> 5 | L2: =IFERROR(VLOOKUP(C2,路飞话务数据源!D:Q,8,FALSE),0) -> 1 | M2: =IFERROR(VLOOKUP(C2,路飞话务数据源!D:Q,9,FALSE),0) -> 10.7 | N2: =IFERROR(VLOOKUP(C2,路飞话务数据源!D:Q,10,FALSE),0) -> 0 | O2: =IFERROR(VLOOKUP(C2,路飞话务数据源!D:Q,11,FALSE),0) -> 0 | P2: =IFERROR(VLOOKUP(C2,路飞话务数据源!D:Q,12,FALSE),0) -> 0 | Q2: =IFERROR(VLOOKUP(C2,路飞话务数据源!D:Q,13,FALSE),0) -> 0 | R2: =IF(OR(TODAY()-E2<=7,F2<5),0,1) -> 1 | S2: =IF(DATEDIF(E2,TODAY(),"M")>=12*3,"3年以上",IF(AND(DATEDIF(E2,TODAY(),"M")>=12*2,DATEDIF(E2,TODAY(),"M")<12*3),"2年-3年",IF(AND(DATEDIF(E2,TODAY(),"M")>=12,DATEDIF(E2,TODAY(),"M")<12*3),"1年-2年",IF(AND(DATEDIF(E2,TODAY(),"M")<12,DATEDIF(E2,TODAY(),"M")>=7),"7月-12月",IF(AND(DATEDIF(E2,TODAY(),"M")<7,DATEDIF(E2,TODAY(),"M")>=3),"4月-6月",IF(DATEDIF(E2,TODAY(),"M")=0,"月内","1-3月")))))) -> 1年-2年 | T2: 明靖 | U2: =SUMIFS(路飞意向数据源!F:F,路飞意向数据源!B:B,A2,路飞意向数据源!C:C,B2,路飞意向数据源!D:D,C2) -> 0
A3: 青岛 | B3: 增值一部 | C3: 张学凯 | D3: zhangxuekai01 | E3: 2023-07-03 | F3: =IFERROR(VLOOKUP(C3,路飞话务数据源!D:Q,2,FALSE),0) -> 30 | G3: =IFERROR(VLOOKUP(C3,路飞话务数据源!D:Q,3,FALSE),0) -> 9 | H3: =IFERROR(VLOOKUP(C3,路飞话务数据源!D:Q,4,FALSE),0) -> 0.3 | I3: =IFERROR(VLOOKUP(C3,路飞话务数据源!D:Q,5,FALSE),0) -> 6 | J3: =IFERROR(VLOOKUP(C3,路飞话务数据源!D:Q,6,FALSE),0) -> 6 | K3: =IFERROR(VLOOKUP(C3,路飞话务数据源!D:Q,7,FALSE),0) -> 4 | L3: =IFERROR(VLOOKUP(C3,路飞话务数据源!D:Q,8,FALSE),0) -> 1 | M3: =IFERROR(VLOOKUP(C3,路飞话务数据源!D:Q,9,FALSE),0) -> 11.733333 | N3: =IFERROR(VLOOKUP(C3,路飞话务数据源!D:Q,10,FALSE),0) -> 0 | O3: =IFERROR(VLOOKUP(C3,路飞话务数据源!D:Q,11,FALSE),0) -> 0 | P3: =IFERROR(VLOOKUP(C3,路飞话务数据源!D:Q,12,FALSE),0) -> 0 | Q3: =IFERROR(VLOOKUP(C3,路飞话务数据源!D:Q,13,FALSE),0) -> 0 | R3: =IF(OR(TODAY()-E3<=7,F3<5),0,1) -> 1 | S3: =IF(DATEDIF(E3,TODAY(),"M")>=12*3,"3年以上",IF(AND(DATEDIF(E3,TODAY(),"M")>=12*2,DATEDIF(E3,TODAY(),"M")<12*3),"2年-3年",IF(AND(DATEDIF(E3,TODAY(),"M")>=12,DATEDIF(E3,TODAY(),"M")<12*3),"1年-2年",IF(AND(DATEDIF(E3,TODAY(),"M")<12,DATEDIF(E3,TODAY(),"M")>=7),"7月-12月",IF(AND(DATEDIF(E3,TODAY(),"M")<7,DATEDIF(E3,TODAY(),"M")>=3),"4月-6月",IF(DATEDIF(E3,TODAY(),"M")=0,"月内","1-3月")))))) -> 1年-2年 | T3: 明靖 | U3: =SUMIFS(路飞意向数据源!F:F,路飞意向数据源!B:B,A3,路飞意向数据源!C:C,B3,路飞意向数据源!D:D,C3) -> 0
A4: 青岛 | B4: 增值一部 | C4: 赵旭阳 | D4: zhaoxuyang03 | E4: 2023-07-24 | F4: =IFERROR(VLOOKUP(C4,路飞话务数据源!D:Q,2,FALSE),0) -> 10 | G4: =IFERROR(VLOOKUP(C4,路飞话务数据源!D:Q,3,FALSE),0) -> 7 | H4: =IFERROR(VLOOKUP(C4,路飞话务数据源!D:Q,4,FALSE),0) -> 0.7 | I4: =IFERROR(VLOOKUP(C4,路飞话务数据源!D:Q,5,FALSE),0) -> 5 | J4: =IFERROR(VLOOKUP(C4,路飞话务数据源!D:Q,6,FALSE),0) -> 4 | K4: =IFERROR(VLOOKUP(C4,路飞话务数据源!D:Q,7,FALSE),0) -> 4 | L4: =IFERROR(VLOOKUP(C4,路飞话务数据源!D:Q,8,FALSE),0) -> 2 | M4: =IFERROR(VLOOKUP(C4,路飞话务数据源!D:Q,9,FALSE),0) -> 16.883333 | N4: =IFERROR(VLOOKUP(C4,路飞话务数据源!D:Q,10,FALSE),0) -> 0 | O4: =IFERROR(VLOOKUP(C4,路飞话务数据源!D:Q,11,FALSE),0) -> 0 | P4: =IFERROR(VLOOKUP(C4,路飞话务数据源!D:Q,12,FALSE),0) -> 0 | Q4: =IFERROR(VLOOKUP(C4,路飞话务数据源!D:Q,13,FALSE),0) -> 0 | R4: =IF(OR(TODAY()-E4<=7,F4<5),0,1) -> 1 | S4: =IF(DATEDIF(E4,TODAY(),"M")>=12*3,"3年以上",IF(AND(DATEDIF(E4,TODAY(),"M")>=12*2,DATEDIF(E4,TODAY(),"M")<12*3),"2年-3年",IF(AND(DATEDIF(E4,TODAY(),"M")>=12,DATEDIF(E4,TODAY(),"M")<12*3),"1年-2年",IF(AND(DATEDIF(E4,TODAY(),"M")<12,DATEDIF(E4,TODAY(),"M")>=7),"7月-12月",IF(AND(DATEDIF(E4,TODAY(),"M")<7,DATEDIF(E4,TODAY(),"M")>=3),"4月-6月",IF(DATEDIF(E4,TODAY(),"M")=0,"月内","1-3月")))))) -> 1年-2年 | T4: 明靖 | U4: =SUMIFS(路飞意向数据源!F:F,路飞意向数据源!B:B,A4,路飞意向数据源!C:C,B4,路飞意向数据源!D:D,C4) -> 0
A5: 青岛 | B5: 增值一部 | C5: 孙俊豪 | D5: sunjunhao | E5: 2023-10-16 | F5: =IFERROR(VLOOKUP(C5,路飞话务数据源!D:Q,2,FALSE),0) -> 51 | G5: =IFERROR(VLOOKUP(C5,路飞话务数据源!D:Q,3,FALSE),0) -> 25 | H5: =IFERROR(VLOOKUP(C5,路飞话务数据源!D:Q,4,FALSE),0) -> 0.49019608 | I5: =IFERROR(VLOOKUP(C5,路飞话务数据源!D:Q,5,FALSE),0) -> 16 | J5: =IFERROR(VLOOKUP(C5,路飞话务数据源!D:Q,6,FALSE),0) -> 12 | K5: =IFERROR(VLOOKUP(C5,路飞话务数据源!D:Q,7,FALSE),0) -> 6 | L5: =IFERROR(VLOOKUP(C5,路飞话务数据源!D:Q,8,FALSE),0) -> 2 | M5: =IFERROR(VLOOKUP(C5,路飞话务数据源!D:Q,9,FALSE),0) -> 26.633333 | N5: =IFERROR(VLOOKUP(C5,路飞话务数据源!D:Q,10,FALSE),0) -> 0 | O5: =IFERROR(VLOOKUP(C5,路飞话务数据源!D:Q,11,FALSE),0) -> 0 | P5: =IFERROR(VLOOKUP(C5,路飞话务数据源!D:Q,12,FALSE),0) -> 0 | Q5: =IFERROR(VLOOKUP(C5,路飞话务数据源!D:Q,13,FALSE),0) -> 0 | R5: =IF(OR(TODAY()-E5<=7,F5<5),0,1) -> 1 | S5: =IF(DATEDIF(E5,TODAY(),"M")>=12*3,"3年以上",IF(AND(DATEDIF(E5,TODAY(),"M")>=12*2,DATEDIF(E5,TODAY(),"M")<12*3),"2年-3年",IF(AND(DATEDIF(E5,TODAY(),"M")>=12,DATEDIF(E5,TODAY(),"M")<12*3),"1年-2年",IF(AND(DATEDIF(E5,TODAY(),"M")<12,DATEDIF(E5,TODAY(),"M")>=7),"7月-12月",IF(AND(DATEDIF(E5,TODAY(),"M")<7,DATEDIF(E5,TODAY(),"M")>=3),"4月-6月",IF(DATEDIF(E5,TODAY(),"M")=0,"月内","1-3月")))))) -> 7月-12月 | T5: 明靖 | U5: =SUMIFS(路飞意向数据源!F:F,路飞意向数据源!B:B,A5,路飞意向数据源!C:C,B5,路飞意向数据源!D:D,C5) -> 0
A6: 青岛 | B6: 增值一部 | C6: 史玉蕾 | D6: shiyulei | E6: 2024-07-23 | F6: =IFERROR(VLOOKUP(C6,路飞话务数据源!D:Q,2,FALSE),0) -> 47 | G6: =IFERROR(VLOOKUP(C6,路飞话务数据源!D:Q,3,FALSE),0) -> 21 | H6: =IFERROR(VLOOKUP(C6,路飞话务数据源!D:Q,4,FALSE),0) -> 0.44680851 | I6: =IFERROR(VLOOKUP(C6,路飞话务数据源!D:Q,5,FALSE),0) -> 15 | J6: =IFERROR(VLOOKUP(C6,路飞话务数据源!D:Q,6,FALSE),0) -> 14 | K6: =IFERROR(VLOOKUP(C6,路飞话务数据源!D:Q,7,FALSE),0) -> 9 | L6: =IFERROR(VLOOKUP(C6,路飞话务数据源!D:Q,8,FALSE),0) -> 0 | M6: =IFERROR(VLOOKUP(C6,路飞话务数据源!D:Q,9,FALSE),0) -> 20.3 | N6: =IFERROR(VLOOKUP(C6,路飞话务数据源!D:Q,10,FALSE),0) -> 0 | O6: =IFERROR(VLOOKUP(C6,路飞话务数据源!D:Q,11,FALSE),0) -> 0 | P6: =IFERROR(VLOOKUP(C6,路飞话务数据源!D:Q,12,FALSE),0) -> 0 | Q6: =IFERROR(VLOOKUP(C6,路飞话务数据源!D:Q,13,FALSE),0) -> 0 | R6: =IF(OR(TODAY()-E6<=7,F6<5),0,1) -> 1 | S6: =IF(DATEDIF(E6,TODAY(),"M")>=12*3,"3年以上",IF(AND(DATEDIF(E6,TODAY(),"M")>=12*2,DATEDIF(E6,TODAY(),"M")<12*3),"2年-3年",IF(AND(DATEDIF(E6,TODAY(),"M")>=12,DATEDIF(E6,TODAY(),"M")<12*3),"1年-2年",IF(AND(DATEDIF(E6,TODAY(),"M")<12,DATEDIF(E6,TODAY(),"M")>=7),"7月-12月",IF(AND(DATEDIF(E6,TODAY(),"M")<7,DATEDIF(E6,TODAY(),"M")>=3),"4月-6月",IF(DATEDIF(E6,TODAY(),"M")=0,"月内","1-3月")))))) -> 1-3月 | T6: 明靖 | U6: =SUMIFS(路飞意向数据源!F:F,路飞意向数据源!B:B,A6,路飞意向数据源!C:C,B6,路飞意向数据源!D:D,C6) -> 0
A7: 青岛 | B7: 增值一部 | C7: 魏广玉 | D7: weiguangyu | E7: 2024-04-12 | F7: =IFERROR(VLOOKUP(C7,路飞话务数据源!D:Q,2,FALSE),0) -> 26 | G7: =IFERROR(VLOOKUP(C7,路飞话务数据源!D:Q,3,FALSE),0) -> 2 | H7: =IFERROR(VLOOKUP(C7,路飞话务数据源!D:Q,4,FALSE),0) -> 0.076923077 | I7: =IFERROR(VLOOKUP(C7,路飞话务数据源!D:Q,5,FALSE),0) -> 0 | J7: =IFERROR(VLOOKUP(C7,路飞话务数据源!D:Q,6,FALSE),0) -> 0 | K7: =IFERROR(VLOOKUP(C7,路飞话务数据源!D:Q,7,FALSE),0) -> 0 | L7: =IFERROR(VLOOKUP(C7,路飞话务数据源!D:Q,8,FALSE),0) -> 0 | M7: =IFERROR(VLOOKUP(C7,路飞话务数据源!D:Q,9,FALSE),0) -> 0.38333333 | N7: =IFERROR(VLOOKUP(C7,路飞话务数据源!D:Q,10,FALSE),0) -> 0 | O7: =IFERROR(VLOOKUP(C7,路飞话务数据源!D:Q,11,FALSE),0) -> 0 | P7: =IFERROR(VLOOKUP(C7,路飞话务数据源!D:Q,12,FALSE),0) -> 0 | Q7: =IFERROR(VLOOKUP(C7,路飞话务数据源!D:Q,13,FALSE),0) -> 0 | R7: =IF(OR(TODAY()-E7<=7,F7<5),0,1) -> 1 | S7: =IF(DATEDIF(E7,TODAY(),"M")>=12*3,"3年以上",IF(AND(DATEDIF(E7,TODAY(),"M")>=12*2,DATEDIF(E7,TODAY(),"M")<12*3),"2年-3年",IF(AND(DATEDIF(E7,TODAY(),"M")>=12,DATEDIF(E7,TODAY(),"M")<12*3),"1年-2年",IF(AND(DATEDIF(E7,TODAY(),"M")<12,DATEDIF(E7,TODAY(),"M")>=7),"7月-12月",IF(AND(DATEDIF(E7,TODAY(),"M")<7,DATEDIF(E7,TODAY(),"M")>=3),"4月-6月",IF(DATEDIF(E7,TODAY(),"M")=0,"月内","1-3月")))))) -> 4月-6月 | T7: 明靖 | U7: =SUMIFS(路飞意向数据源!F:F,路飞意向数据源!B:B,A7,路飞意向数据源!C:C,B7,路飞意向数据源!D:D,C7) -> 0
A8: 青岛 | B8: 增值一部 | C8: 杨嘉艺 | D8: yangjiayi05 | E8: 2024-06-21 | F8: =IFERROR(VLOOKUP(C8,路飞话务数据源!D:Q,2,FALSE),0) -> 0 | G8: =IFERROR(VLOOKUP(C8,路飞话务数据源!D:Q,3,FALSE),0) -> 0 | H8: =IFERROR(VLOOKUP(C8,路飞话务数据源!D:Q,4,FALSE),0) -> 0 | I8: =IFERROR(VLOOKUP(C8,路飞话务数据源!D:Q,5,FALSE),0) -> 0 | J8: =IFERROR(VLOOKUP(C8,路飞话务数据源!D:Q,6,FALSE),0) -> 0 | K8: =IFERROR(VLOOKUP(C8,路飞话务数据源!D:Q,7,FALSE),0) -> 0 | L8: =IFERROR(VLOOKUP(C8,路飞话务数据源!D:Q,8,FALSE),0) -> 0 | M8: =IFERROR(VLOOKUP(C8,路飞话务数据源!D:Q,9,FALSE),0) -> 0 | N8: =IFERROR(VLOOKUP(C8,路飞话务数据源!D:Q,10,FALSE),0) -> 0 | O8: =IFERROR(VLOOKUP(C8,路飞话务数据源!D:Q,11,FALSE),0) -> 0 | P8: =IFERROR(VLOOKUP(C8,路飞话务数据源!D:Q,12,FALSE),0) -> 0 | Q8: =IFERROR(VLOOKUP(C8,路飞话务数据源!D:Q,13,FALSE),0) -> 0 | R8: =IF(OR(TODAY()-E8<=7,F8<5),0,1) -> 0 | S8: =IF(DATEDIF(E8,TODAY(),"M")>=12*3,"3年以上",IF(AND(DATEDIF(E8,TODAY(),"M")>=12*2,DATEDIF(E8,TODAY(),"M")<12*3),"2年-3年",IF(AND(DATEDIF(E8,TODAY(),"M")>=12,DATEDIF(E8,TODAY(),"M")<12*3),"1年-2年",IF(AND(DATEDIF(E8,TODAY(),"M")<12,DATEDIF(E8,TODAY(),"M")>=7),"7月-12月",IF(AND(DATEDIF(E8,TODAY(),"M")<7,DATEDIF(E8,TODAY(),"M")>=3),"4月-6月",IF(DATEDIF(E8,TODAY(),"M")=0,"月内","1-3月")))))) -> 1-3月 | T8: 明靖 | U8: =SUMIFS(路飞意向数据源!F:F,路飞意向数据源!B:B,A8,路飞意向数据源!C:C,B8,路飞意向数据源!D:D,C8) -> 0
A9: 青岛 | B9: 增值一部 | C9: 刘心梦 | D9: liuxinmeng02 | E9: 2023-11-09 | F9: =IFERROR(VLOOKUP(C9,路飞话务数据源!D:Q,2,FALSE),0) -> 6 | G9: =IFERROR(VLOOKUP(C9,路飞话务数据源!D:Q,3,FALSE),0) -> 3 | H9: =IFERROR(VLOOKUP(C9,路飞话务数据源!D:Q,4,FALSE),0) -> 0.5 | I9: =IFERROR(VLOOKUP(C9,路飞话务数据源!D:Q,5,FALSE),0) -> 3 | J9: =IFERROR(VLOOKUP(C9,路飞话务数据源!D:Q,6,FALSE),0) -> 3 | K9: =IFERROR(VLOOKUP(C9,路飞话务数据源!D:Q,7,FALSE),0) -> 1 | L9: =IFERROR(VLOOKUP(C9,路飞话务数据源!D:Q,8,FALSE),0) -> 0 | M9: =IFERROR(VLOOKUP(C9,路飞话务数据源!D:Q,9,FALSE),0) -> 3.6333333 | N9: =IFERROR(VLOOKUP(C9,路飞话务数据源!D:Q,10,FALSE),0) -> 0 | O9: =IFERROR(VLOOKUP(C9,路飞话务数据源!D:Q,11,FALSE),0) -> 0 | P9: =IFERROR(VLOOKUP(C9,路飞话务数据源!D:Q,12,FALSE),0) -> 0 | Q9: =IFERROR(VLOOKUP(C9,路飞话务数据源!D:Q,13,FALSE),0) -> 0 | R9: =IF(OR(TODAY()-E9<=7,F9<5),0,1) -> 1 | S9: =IF(DATEDIF(E9,TODAY(),"M")>=12*3,"3年以上",IF(AND(DATEDIF(E9,TODAY(),"M")>=12*2,DATEDIF(E9,TODAY(),"M")<12*3),"2年-3年",IF(AND(DATEDIF(E9,TODAY(),"M")>=12,DATEDIF(E9,TODAY(),"M")<12*3),"1年-2年",IF(AND(DATEDIF(E9,TODAY(),"M")<12,DATEDIF(E9,TODAY(),"M")>=7),"7月-12月",IF(AND(DATEDIF(E9,TODAY(),"M")<7,DATEDIF(E9,TODAY(),"M")>=3),"4月-6月",IF(DATEDIF(E9,TODAY(),"M")=0,"月内","1-3月")))))) -> 7月-12月 | T9: 明靖 | U9: =SUMIFS(路飞意向数据源!F:F,路飞意向数据源!B:B,A9,路飞意向数据源!C:C,B9,路飞意向数据源!D:D,C9) -> 0
A10: 青岛 | B10: 增值一部 | C10: 焦泽 | D10: jiaoze | E10: 2023-10-18 | F10: =IFERROR(VLOOKUP(C10,路飞话务数据源!D:Q,2,FALSE),0) -> 8 | G10: =IFERROR(VLOOKUP(C10,路飞话务数据源!D:Q,3,FALSE),0) -> 4 | H10: =IFERROR(VLOOKUP(C10,路飞话务数据源!D:Q,4,FALSE),0) -> 0.5 | I10: =IFERROR(VLOOKUP(C10,路飞话务数据源!D:Q,5,FALSE),0) -> 3 | J10: =IFERROR(VLOOKUP(C10,路飞话务数据源!D:Q,6,FALSE),0) -> 1 | K10: =IFERROR(VLOOKUP(C10,路飞话务数据源!D:Q,7,FALSE),0) -> 1 | L10: =IFERROR(VLOOKUP(C10,路飞话务数据源!D:Q,8,FALSE),0) -> 0 | M10: =IFERROR(VLOOKUP(C10,路飞话务数据源!D:Q,9,FALSE),0) -> 3.2 | N10: =IFERROR(VLOOKUP(C10,路飞话务数据源!D:Q,10,FALSE),0) -> 0 | O10: =IFERROR(VLOOKUP(C10,路飞话务数据源!D:Q,11,FALSE),0) -> 0 | P10: =IFERROR(VLOOKUP(C10,路飞话务数据源!D:Q,12,FALSE),0) -> 0 | Q10: =IFERROR(VLOOKUP(C10,路飞话务数据源!D:Q,13,FALSE),0) -> 0 | R10: =IF(OR(TODAY()-E10<=7,F10<5),0,1) -> 1 | S10: =IF(DATEDIF(E10,TODAY(),"M")>=12*3,"3年以上",IF(AND(DATEDIF(E10,TODAY(),"M")>=12*2,DATEDIF(E10,TODAY(),"M")<12*3),"2年-3年",IF(AND(DATEDIF(E10,TODAY(),"M")>=12,DATEDIF(E10,TODAY(),"M")<12*3),"1年-2年",IF(AND(DATEDIF(E10,TODAY(),"M")<12,DATEDIF(E10,TODAY(),"M")>=7),"7月-12月",IF(AND(DATEDIF(E10,TODAY(),"M")<7,DATEDIF(E10,TODAY(),"M")>=3),"4月-6月",IF(DATEDIF(E10,TODAY(),"M")=0,"月内","1-3月")))))) -> 7月-12月 | T10: 明靖 | U10: =SUMIFS(路飞意向数据源!F:F,路飞意向数据源!B:B,A10,路飞意向数据源!C:C,B10,路飞意向数据源!D:D,C10) -> 0
A11: 杭州 | B11: 物流行业一部 | C11: 徐彬勃 | D11: xubinbo | E11: 2019-09-06 | F11: =IFERROR(VLOOKUP(C11,路飞话务数据源!D:Q,2,FALSE),0) -> 0 | G11: =IFERROR(VLOOKUP(C11,路飞话务数据源!D:Q,3,FALSE),0) -> 0 | H11: =IFERROR(VLOOKUP(C11,路飞话务数据源!D:Q,4,FALSE),0) -> 0 | I11: =IFERROR(VLOOKUP(C11,路飞话务数据源!D:Q,5,FALSE),0) -> 0 | J11: =IFERROR(VLOOKUP(C11,路飞话务数据源!D:Q,6,FALSE),0) -> 0 | K11: =IFERROR(VLOOKUP(C11,路飞话务数据源!D:Q,7,FALSE),0) -> 0 | L11: =IFERROR(VLOOKUP(C11,路飞话务数据源!D:Q,8,FALSE),0) -> 0 | M11: =IFERROR(VLOOKUP(C11,路飞话务数据源!D:Q,9,FALSE),0) -> 0 | N11: =IFERROR(VLOOKUP(C11,路飞话务数据源!D:Q,10,FALSE),0) -> 1 | O11: =IFERROR(VLOOKUP(C11,路飞话务数据源!D:Q,11,FALSE),0) -> 0 | P11: =IFERROR(VLOOKUP(C11,路飞话务数据源!D:Q,12,FALSE),0) -> 0 | Q11: =IFERROR(VLOOKUP(C11,路飞话务数据源!D:Q,13,FALSE),0) -> 60 | R11: =IF(OR(TODAY()-E11<=7,F11<5),0,1) -> 0 | S11: =IF(DATEDIF(E11,TODAY(),"M")>=12*3,"3年以上",IF(AND(DATEDIF(E11,TODAY(),"M")>=12*2,DATEDIF(E11,TODAY(),"M")<12*3),"2年-3年",IF(AND(DATEDIF(E11,TODAY(),"M")>=12,DATEDIF(E11,TODAY(),"M")<12*3),"1年-2年",IF(AND(DATEDIF(E11,TODAY(),"M")<12,DATEDIF(E11,TODAY(),"M")>=7),"7月-12月",IF(AND(DATEDIF(E11,TODAY(),"M")<7,DATEDIF(E11,TODAY(),"M")>=3),"4月-6月",IF(DATEDIF(E11,TODAY(),"M")=0,"月内","1-3月")))))) -> 3年以上 | T11: 冯凯 | U11: =SUMIFS(路飞意向数据源!F:F,路飞意向数据源!B:B,A11,路飞意向数据源!C:C,B11,路飞意向数据源!D:D,C11) -> 0
A12: 杭州 | B12: 物流行业一部 | C12: 叶佳妮 | D12: yejiani | E12: 2021-01-14 | F12: =IFERROR(VLOOKUP(C12,路飞话务数据源!D:Q,2,FALSE),0) -> 0 | G12: =IFERROR(VLOOKUP(C12,路飞话务数据源!D:Q,3,FALSE),0) -> 0 | H12: =IFERROR(VLOOKUP(C12,路飞话务数据源!D:Q,4,FALSE),0) -> 0 | I12: =IFERROR(VLOOKUP(C12,路飞话务数据源!D:Q,5,FALSE),0) -> 0 | J12: =IFERROR(VLOOKUP(C12,路飞话务数据源!D:Q,6,FALSE),0) -> 0 | K12: =IFERROR(VLOOKUP(C12,路飞话务数据源!D:Q,7,FALSE),0) -> 0 | L12: =IFERROR(VLOOKUP(C12,路飞话务数据源!D:Q,8,FALSE),0) -> 0 | M12: =IFERROR(VLOOKUP(C12,路飞话务数据源!D:Q,9,FALSE),0) -> 0 | N12: =IFERROR(VLOOKUP(C12,路飞话务数据源!D:Q,10,FALSE),0) -> 0 | O12: =IFERROR(VLOOKUP(C12,路飞话务数据源!D:Q,11,FALSE),0) -> 0 | P12: =IFERROR(VLOOKUP(C12,路飞话务数据源!D:Q,12,FALSE),0) -> 0 | Q12: =IFERROR(VLOOKUP(C12,路飞话务数据源!D:Q,13,FALSE),0) -> 0 | R12: =IF(OR(TODAY()-E12<=7,F12<5),0,1) -> 0 | S12: =IF(DATEDIF(E12,TODAY(),"M")>=12*3,"3年以上",IF(AND(DATEDIF(E12,TODAY(),"M")>=12*2,DATEDIF(E12,TODAY(),"M")<12*3),"2年-3年",IF(AND(DATEDIF(E12,TODAY(),"M")>=12,DATEDIF(E12,TODAY(),"M")<12*3),"1年-2年",IF(AND(DATEDIF(E12,TODAY(),"M")<12,DATEDIF(E12,TODAY(),"M")>=7),"7月-12月",IF(AND(DATEDIF(E12,TODAY(),"M")<7,DATEDIF(E12,TODAY(),"M")>=3),"4月-6月",IF(DATEDIF(E12,TODAY(),"M")=0,"月内","1-3月")))))) -> 3年以上 | T12: 冯凯 | U12: =SUMIFS(路飞意向数据源!F:F,路飞意向数据源!B:B,A12,路飞意向数据源!C:C,B12,路飞意向数据源!D:D,C12) -> 0
A13: 杭州 | B13: 物流行业一部 | C13: 邱骏 | D13: qiujun05 | E13: 2021-09-08 | F13: =IFERROR(VLOOKUP(C13,路飞话务数据源!D:Q,2,FALSE),0) -> 0 | G13: =IFERROR(VLOOKUP(C13,路飞话务数据源!D:Q,3,FALSE),0) -> 0 | H13: =IFERROR(VLOOKUP(C13,路飞话务数据源!D:Q,4,FALSE),0) -> 0 | I13: =IFERROR(VLOOKUP(C13,路飞话务数据源!D:Q,5,FALSE),0) -> 0 | J13: =IFERROR(VLOOKUP(C13,路飞话务数据源!D:Q,6,FALSE),0) -> 0 | K13: =IFERROR(VLOOKUP(C13,路飞话务数据源!D:Q,7,FALSE),0) -> 0 | L13: =IFERROR(VLOOKUP(C13,路飞话务数据源!D:Q,8,FALSE),0) -> 0 | M13: =IFERROR(VLOOKUP(C13,路飞话务数据源!D:Q,9,FALSE),0) -> 0 | N13: =IFERROR(VLOOKUP(C13,路飞话务数据源!D:Q,10,FALSE),0) -> 1 | O13: =IFERROR(VLOOKUP(C13,路飞话务数据源!D:Q,11,FALSE),0) -> 0 | P13: =IFERROR(VLOOKUP(C13,路飞话务数据源!D:Q,12,FALSE),0) -> 0 | Q13: =IFERROR(VLOOKUP(C13,路飞话务数据源!D:Q,13,FALSE),0) -> 83 | R13: =IF(OR(TODAY()-E13<=7,F13<5),0,1) -> 0 | S13: =IF(DATEDIF(E13,TODAY(),"M")>=12*3,"3年以上",IF(AND(DATEDIF(E13,TODAY(),"M")>=12*2,DATEDIF(E13,TODAY(),"M")<12*3),"2年-3年",IF(AND(DATEDIF(E13,TODAY(),"M")>=12,DATEDIF(E13,TODAY(),"M")<12*3),"1年-2年",IF(AND(DATEDIF(E13,TODAY(),"M")<12,DATEDIF(E13,TODAY(),"M")>=7),"7月-12月",IF(AND(DATEDIF(E13,TODAY(),"M")<7,DATEDIF(E13,TODAY(),"M")>=3),"4月-6月",IF(DATEDIF(E13,TODAY(),"M")=0,"月内","1-3月")))))) -> 2年-3年 | T13: 冯凯 | U13: =SUMIFS(路飞意向数据源!F:F,路飞意向数据源!B:B,A13,路飞意向数据源!C:C,B13,路飞意向数据源!D:D,C13) -> 0
... A30: 济南 | B30: 新签四部 | C30: 邵荣晶 | D30: shaorongjing | E30: 2024-07-10 | F30: =IFERROR(VLOOKUP(C30,路飞话务数据源!D:Q,2,FALSE),0) -> 277 | G30: =IFERROR(VLOOKUP(C30,路飞话务数据源!D:Q,3,FALSE),0) -> 100 | H30: =IFERROR(VLOOKUP(C30,路飞话务数据源!D:Q,4,FALSE),0) -> 0.36101083 | I30: =IFERROR(VLOOKUP(C30,路飞话务数据源!D:Q,5,FALSE),0) -> 57 | J30: =IFERROR(VLOOKUP(C30,路飞话务数据源!D:Q,6,FALSE),0) -> 39 | K30: =IFERROR(VLOOKUP(C30,路飞话务数据源!D:Q,7,FALSE),0) -> 27 | L30: =IFERROR(VLOOKUP(C30,路飞话务数据源!D:Q,8,FALSE),0) -> 3 | M30: =IFERROR(VLOOKUP(C30,路飞话务数据源!D:Q,9,FALSE),0) -> 79.933333 | N30: =IFERROR(VLOOKUP(C30,路飞话务数据源!D:Q,10,FALSE),0) -> 0 | O30: =IFERROR(VLOOKUP(C30,路飞话务数据源!D:Q,11,FALSE),0) -> 0 | P30: =IFERROR(VLOOKUP(C30,路飞话务数据源!D:Q,12,FALSE),0) -> 0 | Q30: =IFERROR(VLOOKUP(C30,路飞话务数据源!D:Q,13,FALSE),0) -> 0 | R30: =IF(OR(TODAY()-E30<=7,F30<5),0,1) -> 1 | S30: =IF(DATEDIF(E30,TODAY(),"M")>=12*3,"3年以上",IF(AND(DATEDIF(E30,TODAY(),"M")>=12*2,DATEDIF(E30,TODAY(),"M")<12*3),"2年-3年",IF(AND(DATEDIF(E30,TODAY(),"M")>=12,DATEDIF(E30,TODAY(),"M")<12*3),"1年-2年",IF(AND(DATEDIF(E30,TODAY(),"M")<12,DATEDIF(E30,TODAY(),"M")>=7),"7月-12月",IF(AND(DATEDIF(E30,TODAY(),"M")<7,DATEDIF(E30,TODAY(),"M")>=3),"4月-6月",IF(DATEDIF(E30,TODAY(),"M")=0,"月内","1-3月")))))) -> 1-3月 | T30: 梁梦飞 | U30: =SUMIFS(路飞意向数据源!F:F,路飞意向数据源!B:B,A30,路飞意向数据源!C:C,B30,路飞意向数据源!D:D,C30) -> 0
A31: 济南 | B31: 新签四部 | C31: 宋强 | D31: songqiang04 | E31: 2024-07-19 | F31: =IFERROR(VLOOKUP(C31,路飞话务数据源!D:Q,2,FALSE),0) -> 288 | G31: =IFERROR(VLOOKUP(C31,路飞话务数据源!D:Q,3,FALSE),0) -> 123 | H31: =IFERROR(VLOOKUP(C31,路飞话务数据源!D:Q,4,FALSE),0) -> 0.42708333 | I31: =IFERROR(VLOOKUP(C31,路飞话务数据源!D:Q,5,FALSE),0) -> 50 | J31: =IFERROR(VLOOKUP(C31,路飞话务数据源!D:Q,6,FALSE),0) -> 31 | K31: =IFERROR(VLOOKUP(C31,路飞话务数据源!D:Q,7,FALSE),0) -> 16 | L31: =IFERROR(VLOOKUP(C31,路飞话务数据源!D:Q,8,FALSE),0) -> 1 | M31: =IFERROR(VLOOKUP(C31,路飞话务数据源!D:Q,9,FALSE),0) -> 67.25 | N31: =IFERROR(VLOOKUP(C31,路飞话务数据源!D:Q,10,FALSE),0) -> 0 | O31: 0 | P31: =IFERROR(VLOOKUP(C31,路飞话务数据源!D:Q,12,FALSE),0) -> 0 | Q31: =IFERROR(VLOOKUP(C31,路飞话务数据源!D:Q,13,FALSE),0) -> 0 | R31: =IF(OR(TODAY()-E31<=7,F31<5),0,1) -> 1 | S31: =IF(DATEDIF(E31,TODAY(),"M")>=12*3,"3年以上",IF(AND(DATEDIF(E31,TODAY(),"M")>=12*2,DATEDIF(E31,TODAY(),"M")<12*3),"2年-3年",IF(AND(DATEDIF(E31,TODAY(),"M")>=12,DATEDIF(E31,TODAY(),"M")<12*3),"1年-2年",IF(AND(DATEDIF(E31,TODAY(),"M")<12,DATEDIF(E31,TODAY(),"M")>=7),"7月-12月",IF(AND(DATEDIF(E31,TODAY(),"M")<7,DATEDIF(E31,TODAY(),"M")>=3),"4月-6月",IF(DATEDIF(E31,TODAY(),"M")=0,"月内","1-3月")))))) -> 1-3月 | T31: 梁梦飞 | U31: =SUMIFS(路飞意向数据源!F:F,路飞意向数据源!B:B,A31,路飞意向数据源!C:C,B31,路飞意向数据源!D:D,C31) -> 0
A32: 济南 | B32: 新签四部 | C32: 时荣飞 | D32: shirongfei | E32: 2024-07-24 | F32: =IFERROR(VLOOKUP(C32,路飞话务数据源!D:Q,2,FALSE),0) -> 257 | G32: =IFERROR(VLOOKUP(C32,路飞话务数据源!D:Q,3,FALSE),0) -> 118 | H32: =IFERROR(VLOOKUP(C32,路飞话务数据源!D:Q,4,FALSE),0) -> 0.45914397 | I32: =IFERROR(VLOOKUP(C32,路飞话务数据源!D:Q,5,FALSE),0) -> 43 | J32: =IFERROR(VLOOKUP(C32,路飞话务数据源!D:Q,6,FALSE),0) -> 30 | K32: =IFERROR(VLOOKUP(C32,路飞话务数据源!D:Q,7,FALSE),0) -> 10 | L32: =IFERROR(VLOOKUP(C32,路飞话务数据源!D:Q,8,FALSE),0) -> 1 | M32: =IFERROR(VLOOKUP(C32,路飞话务数据源!D:Q,9,FALSE),0) -> 63.583333 | N32: =IFERROR(VLOOKUP(C32,路飞话务数据源!D:Q,10,FALSE),0) -> 0 | O32: =IFERROR(VLOOKUP(C32,路飞话务数据源!D:Q,11,FALSE),0) -> 0 | P32: =IFERROR(VLOOKUP(C32,路飞话务数据源!D:Q,12,FALSE),0) -> 0 | Q32: =IFERROR(VLOOKUP(C32,路飞话务数据源!D:Q,13,FALSE),0) -> 0 | R32: =IF(OR(TODAY()-E32<=7,F32<5),0,1) -> 1 | S32: =IF(DATEDIF(E32,TODAY(),"M")>=12*3,"3年以上",IF(AND(DATEDIF(E32,TODAY(),"M")>=12*2,DATEDIF(E32,TODAY(),"M")<12*3),"2年-3年",IF(AND(DATEDIF(E32,TODAY(),"M")>=12,DATEDIF(E32,TODAY(),"M")<12*3),"1年-2年",IF(AND(DATEDIF(E32,TODAY(),"M")<12,DATEDIF(E32,TODAY(),"M")>=7),"7月-12月",IF(AND(DATEDIF(E32,TODAY(),"M")<7,DATEDIF(E32,TODAY(),"M")>=3),"4月-6月",IF(DATEDIF(E32,TODAY(),"M")=0,"月内","1-3月")))))) -> 1-3月 | T32: 梁梦飞 | U32: =SUMIFS(路飞意向数据源!F:F,路飞意向数据源!B:B,A32,路飞意向数据源!C:C,B32,路飞意向数据源!D:D,C32) -> 0
A33: 杭州 | B33: 地推一部 | C33: 吴家宝 | D33: wujiabao03 | E33: 2024-08-26 | F33: =IFERROR(VLOOKUP(C33,路飞话务数据源!D:Q,2,FALSE),0) -> 0 | G33: =IFERROR(VLOOKUP(C33,路飞话务数据源!D:Q,3,FALSE),0) -> 0 | H33: =IFERROR(VLOOKUP(C33,路飞话务数据源!D:Q,4,FALSE),0) -> 0 | I33: =IFERROR(VLOOKUP(C33,路飞话务数据源!D:Q,5,FALSE),0) -> 0 | J33: =IFERROR(VLOOKUP(C33,路飞话务数据源!D:Q,6,FALSE),0) -> 0 | K33: =IFERROR(VLOOKUP(C33,路飞话务数据源!D:Q,7,FALSE),0) -> 0 | L33: =IFERROR(VLOOKUP(C33,路飞话务数据源!D:Q,8,FALSE),0) -> 0 | M33: =IFERROR(VLOOKUP(C33,路飞话务数据源!D:Q,9,FALSE),0) -> 0 | N33: =IFERROR(VLOOKUP(C33,路飞话务数据源!D:Q,10,FALSE),0) -> 0 | O33: =IFERROR(VLOOKUP(C33,路飞话务数据源!D:Q,11,FALSE),0) -> 0 | P33: =IFERROR(VLOOKUP(C33,路飞话务数据源!D:Q,12,FALSE),0) -> 0 | Q33: =IFERROR(VLOOKUP(C33,路飞话务数据源!D:Q,13,FALSE),0) -> 0 | R33: =IF(OR(TODAY()-E33<=7,F33<5),0,1) -> 0 | S33: =IF(DATEDIF(E33,TODAY(),"M")>=12*3,"3年以上",IF(AND(DATEDIF(E33,TODAY(),"M")>=12*2,DATEDIF(E33,TODAY(),"M")<12*3),"2年-3年",IF(AND(DATEDIF(E33,TODAY(),"M")>=12,DATEDIF(E33,TODAY(),"M")<12*3),"1年-2年",IF(AND(DATEDIF(E33,TODAY(),"M")<12,DATEDIF(E33,TODAY(),"M")>=7),"7月-12月",IF(AND(DATEDIF(E33,TODAY(),"M")<7,DATEDIF(E33,TODAY(),"M")>=3),"4月-6月",IF(DATEDIF(E33,TODAY(),"M")=0,"月内","1-3月")))))) -> 月内 | T33: 张日昂 | U33: =SUMIFS(路飞意向数据源!F:F,路飞意向数据源!B:B,A33,路飞意向数据源!C:C,B33,路飞意向数据源!D:D,C33) -> 0
A34: 杭州 | B34: 地推一部 | C34: 刘安宇 | D34: liuanyu | E34: 2024-01-19 | F34: =IFERROR(VLOOKUP(C34,路飞话务数据源!D:Q,2,FALSE),0) -> 0 | G34: =IFERROR(VLOOKUP(C34,路飞话务数据源!D:Q,3,FALSE),0) -> 0 | H34: =IFERROR(VLOOKUP(C34,路飞话务数据源!D:Q,4,FALSE),0) -> 0 | I34: =IFERROR(VLOOKUP(C34,路飞话务数据源!D:Q,5,FALSE),0) -> 0 | J34: =IFERROR(VLOOKUP(C34,路飞话务数据源!D:Q,6,FALSE),0) -> 0 | K34: =IFERROR(VLOOKUP(C34,路飞话务数据源!D:Q,7,FALSE),0) -> 0 | L34: =IFERROR(VLOOKUP(C34,路飞话务数据源!D:Q,8,FALSE),0) -> 0 | M34: =IFERROR(VLOOKUP(C34,路飞话务数据源!D:Q,9,FALSE),0) -> 0 | N34: 0 | O34: 0 | P34: =IFERROR(VLOOKUP(C34,路飞话务数据源!D:Q,12,FALSE),0) -> 0 | Q34: =IFERROR(VLOOKUP(C34,路飞话务数据源!D:Q,13,FALSE),0) -> 0 | R34: =IF(OR(TODAY()-E34<=7,F34<5),0,1) -> 0 | S34: =IF(DATEDIF(E34,TODAY(),"M")>=12*3,"3年以上",IF(AND(DATEDIF(E34,TODAY(),"M")>=12*2,DATEDIF(E34,TODAY(),"M")<12*3),"2年-3年",IF(AND(DATEDIF(E34,TODAY(),"M")>=12,DATEDIF(E34,TODAY(),"M")<12*3),"1年-2年",IF(AND(DATEDIF(E34,TODAY(),"M")<12,DATEDIF(E34,TODAY(),"M")>=7),"7月-12月",IF(AND(DATEDIF(E34,TODAY(),"M")<7,DATEDIF(E34,TODAY(),"M")>=3),"4月-6月",IF(DATEDIF(E34,TODAY(),"M")=0,"月内","1-3月")))))) -> 7月-12月 | T34: 张日昂 | U34: =SUMIFS(路飞意向数据源!F:F,路飞意向数据源!B:B,A34,路飞意向数据源!C:C,B34,路飞意向数据源!D:D,C34) -> 0
A35: 杭州 | B35: 地推一部 | C35: 汪庆善 | D35: wangqingshan | E35: 2024-03-11 | F35: =IFERROR(VLOOKUP(C35,路飞话务数据源!D:Q,2,FALSE),0) -> 0 | G35: =IFERROR(VLOOKUP(C35,路飞话务数据源!D:Q,3,FALSE),0) -> 0 | H35: =IFERROR(VLOOKUP(C35,路飞话务数据源!D:Q,4,FALSE),0) -> 0 | I35: =IFERROR(VLOOKUP(C35,路飞话务数据源!D:Q,5,FALSE),0) -> 0 | J35: =IFERROR(VLOOKUP(C35,路飞话务数据源!D:Q,6,FALSE),0) -> 0 | K35: =IFERROR(VLOOKUP(C35,路飞话务数据源!D:Q,7,FALSE),0) -> 0 | L35: =IFERROR(VLOOKUP(C35,路飞话务数据源!D:Q,8,FALSE),0) -> 0 | M35: =IFERROR(VLOOKUP(C35,路飞话务数据源!D:Q,9,FALSE),0) -> 0 | N35: =IFERROR(VLOOKUP(C35,路飞话务数据源!D:Q,10,FALSE),0) -> 0 | O35: =IFERROR(VLOOKUP(C35,路飞话务数据源!D:Q,11,FALSE),0) -> 0 | P35: =IFERROR(VLOOKUP(C35,路飞话务数据源!D:Q,12,FALSE),0) -> 0 | Q35: =IFERROR(VLOOKUP(C35,路飞话务数据源!D:Q,13,FALSE),0) -> 0 | R35: =IF(OR(TODAY()-E35<=7,F35<5),0,1) -> 0 | S35: =IF(DATEDIF(E35,TODAY(),"M")>=12*3,"3年以上",IF(AND(DATEDIF(E35,TODAY(),"M")>=12*2,DATEDIF(E35,TODAY(),"M")<12*3),"2年-3年",IF(AND(DATEDIF(E35,TODAY(),"M")>=12,DATEDIF(E35,TODAY(),"M")<12*3),"1年-2年",IF(AND(DATEDIF(E35,TODAY(),"M")<12,DATEDIF(E35,TODAY(),"M")>=7),"7月-12月",IF(AND(DATEDIF(E35,TODAY(),"M")<7,DATEDIF(E35,TODAY(),"M")>=3),"4月-6月",IF(DATEDIF(E35,TODAY(),"M")=0,"月内","1-3月")))))) -> 4月-6月 | T35: 张日昂 | U35: =SUMIFS(路飞意向数据源!F:F,路飞意向数据源!B:B,A35,路飞意向数据源!C:C,B35,路飞意向数据源!D:D,C35) -> 0
A36: 杭州 | B36: 地推一部 | C36: 许寿方 | D36: xushoufang | E36: 2024-06-25 | F36: =IFERROR(VLOOKUP(C36,路飞话务数据源!D:Q,2,FALSE),0) -> 0 | G36: =IFERROR(VLOOKUP(C36,路飞话务数据源!D:Q,3,FALSE),0) -> 0 | H36: =IFERROR(VLOOKUP(C36,路飞话务数据源!D:Q,4,FALSE),0) -> 0 | I36: =IFERROR(VLOOKUP(C36,路飞话务数据源!D:Q,5,FALSE),0) -> 0 | J36: =IFERROR(VLOOKUP(C36,路飞话务数据源!D:Q,6,FALSE),0) -> 0 | K36: =IFERROR(VLOOKUP(C36,路飞话务数据源!D:Q,7,FALSE),0) -> 0 | L36: =IFERROR(VLOOKUP(C36,路飞话务数据源!D:Q,8,FALSE),0) -> 0 | M36: =IFERROR(VLOOKUP(C36,路飞话务数据源!D:Q,9,FALSE),0) -> 0 | N36: =IFERROR(VLOOKUP(C36,路飞话务数据源!D:Q,10,FALSE),0) -> 0 | O36: =IFERROR(VLOOKUP(C36,路飞话务数据源!D:Q,11,FALSE),0) -> 0 | P36: =IFERROR(VLOOKUP(C36,路飞话务数据源!D:Q,12,FALSE),0) -> 0 | Q36: =IFERROR(VLOOKUP(C36,路飞话务数据源!D:Q,13,FALSE),0) -> 0 | R36: =IF(OR(TODAY()-E36<=7,F36<5),0,1) -> 0 | S36: =IF(DATEDIF(E36,TODAY(),"M")>=12*3,"3年以上",IF(AND(DATEDIF(E36,TODAY(),"M")>=12*2,DATEDIF(E36,TODAY(),"M")<12*3),"2年-3年",IF(AND(DATEDIF(E36,TODAY(),"M")>=12,DATEDIF(E36,TODAY(),"M")<12*3),"1年-2年",IF(AND(DATEDIF(E36,TODAY(),"M")<12,DATEDIF(E36,TODAY(),"M")>=7),"7月-12月",IF(AND(DATEDIF(E36,TODAY(),"M")<7,DATEDIF(E36,TODAY(),"M")>=3),"4月-6月",IF(DATEDIF(E36,TODAY(),"M")=0,"月内","1-3月")))))) -> 1-3月 | T36: 张日昂 | U36: =SUMIFS(路飞意向数据源!F:F,路飞意向数据源!B:B,A36,路飞意向数据源!C:C,B36,路飞意向数据源!D:D,C36) -> 0
A37: 杭州 | B37: 地推一部 | C37: 蔡晨煜 | D37: caichenyu | E37: 2024-06-26 | F37: =IFERROR(VLOOKUP(C37,路飞话务数据源!D:Q,2,FALSE),0) -> 0 | G37: =IFERROR(VLOOKUP(C37,路飞话务数据源!D:Q,3,FALSE),0) -> 0 | H37: =IFERROR(VLOOKUP(C37,路飞话务数据源!D:Q,4,FALSE),0) -> 0 | I37: =IFERROR(VLOOKUP(C37,路飞话务数据源!D:Q,5,FALSE),0) -> 0 | J37: =IFERROR(VLOOKUP(C37,路飞话务数据源!D:Q,6,FALSE),0) -> 0 | K37: =IFERROR(VLOOKUP(C37,路飞话务数据源!D:Q,7,FALSE),0) -> 0 | L37: =IFERROR(VLOOKUP(C37,路飞话务数据源!D:Q,8,FALSE),0) -> 0 | M37: =IFERROR(VLOOKUP(C37,路飞话务数据源!D:Q,9,FALSE),0) -> 0 | N37: =IFERROR(VLOOKUP(C37,路飞话务数据源!D:Q,10,FALSE),0) -> 0 | O37: =IFERROR(VLOOKUP(C37,路飞话务数据源!D:Q,11,FALSE),0) -> 0 | P37: =IFERROR(VLOOKUP(C37,路飞话务数据源!D:Q,12,FALSE),0) -> 0 | Q37: =IFERROR(VLOOKUP(C37,路飞话务数据源!D:Q,13,FALSE),0) -> 0 | R37: =IF(OR(TODAY()-E37<=7,F37<5),0,1) -> 0 | S37: =IF(DATEDIF(E37,TODAY(),"M")>=12*3,"3年以上",IF(AND(DATEDIF(E37,TODAY(),"M")>=12*2,DATEDIF(E37,TODAY(),"M")<12*3),"2年-3年",IF(AND(DATEDIF(E37,TODAY(),"M")>=12,DATEDIF(E37,TODAY(),"M")<12*3),"1年-2年",IF(AND(DATEDIF(E37,TODAY(),"M")<12,DATEDIF(E37,TODAY(),"M")>=7),"7月-12月",IF(AND(DATEDIF(E37,TODAY(),"M")<7,DATEDIF(E37,TODAY(),"M")>=3),"4月-6月",IF(DATEDIF(E37,TODAY(),"M")=0,"月内","1-3月")))))) -> 1-3月 | T37: 张日昂 | U37: =SUMIFS(路飞意向数据源!F:F,路飞意向数据源!B:B,A37,路飞意向数据源!C:C,B37,路飞意向数据源!D:D,C37) -> 0
A38: 杭州 | B38: 地推一部 | C38: 杨宁 | D38: yangning15 | E38: 2024-07-29 | F38: =IFERROR(VLOOKUP(C38,路飞话务数据源!D:Q,2,FALSE),0) -> 2 | G38: =IFERROR(VLOOKUP(C38,路飞话务数据源!D:Q,3,FALSE),0) -> 0 | H38: =IFERROR(VLOOKUP(C38,路飞话务数据源!D:Q,4,FALSE),0) -> 0 | I38: =IFERROR(VLOOKUP(C38,路飞话务数据源!D:Q,5,FALSE),0) -> 0 | J38: =IFERROR(VLOOKUP(C38,路飞话务数据源!D:Q,6,FALSE),0) -> 0 | K38: =IFERROR(VLOOKUP(C38,路飞话务数据源!D:Q,7,FALSE),0) -> 0 | L38: =IFERROR(VLOOKUP(C38,路飞话务数据源!D:Q,8,FALSE),0) -> 0 | M38: =IFERROR(VLOOKUP(C38,路飞话务数据源!D:Q,9,FALSE),0) -> 0 | N38: =IFERROR(VLOOKUP(C38,路飞话务数据源!D:Q,10,FALSE),0) -> 0 | O38: =IFERROR(VLOOKUP(C38,路飞话务数据源!D:Q,11,FALSE),0) -> 0 | P38: =IFERROR(VLOOKUP(C38,路飞话务数据源!D:Q,12,FALSE),0) -> 0 | Q38: =IFERROR(VLOOKUP(C38,路飞话务数据源!D:Q,13,FALSE),0) -> 0 | R38: =IF(OR(TODAY()-E38<=7,F38<5),0,1) -> 0 | S38: =IF(DATEDIF(E38,TODAY(),"M")>=12*3,"3年以上",IF(AND(DATEDIF(E38,TODAY(),"M")>=12*2,DATEDIF(E38,TODAY(),"M")<12*3),"2年-3年",IF(AND(DATEDIF(E38,TODAY(),"M")>=12,DATEDIF(E38,TODAY(),"M")<12*3),"1年-2年",IF(AND(DATEDIF(E38,TODAY(),"M")<12,DATEDIF(E38,TODAY(),"M")>=7),"7月-12月",IF(AND(DATEDIF(E38,TODAY(),"M")<7,DATEDIF(E38,TODAY(),"M")>=3),"4月-6月",IF(DATEDIF(E38,TODAY(),"M")=0,"月内","1-3月")))))) -> 1-3月 | T38: 张日昂 | U38: =SUMIFS(路飞意向数据源!F:F,路飞意向数据源!B:B,A38,路飞意向数据源!C:C,B38,路飞意向数据源!D:D,C38) -> 0
A39: 杭州 | B39: 地推一部 | C39: 马帅 | D39: mashuai12 | E39: 2024-08-02 | F39: =IFERROR(VLOOKUP(C39,路飞话务数据源!D:Q,2,FALSE),0) -> 0 | G39: =IFERROR(VLOOKUP(C39,路飞话务数据源!D:Q,3,FALSE),0) -> 0 | H39: =IFERROR(VLOOKUP(C39,路飞话务数据源!D:Q,4,FALSE),0) -> 0 | I39: =IFERROR(VLOOKUP(C39,路飞话务数据源!D:Q,5,FALSE),0) -> 0 | J39: =IFERROR(VLOOKUP(C39,路飞话务数据源!D:Q,6,FALSE),0) -> 0 | K39: =IFERROR(VLOOKUP(C39,路飞话务数据源!D:Q,7,FALSE),0) -> 0 | L39: =IFERROR(VLOOKUP(C39,路飞话务数据源!D:Q,8,FALSE),0) -> 0 | M39: =IFERROR(VLOOKUP(C39,路飞话务数据源!D:Q,9,FALSE),0) -> 0 | N39: =IFERROR(VLOOKUP(C39,路飞话务数据源!D:Q,10,FALSE),0) -> 0 | O39: =IFERROR(VLOOKUP(C39,路飞话务数据源!D:Q,11,FALSE),0) -> 0 | P39: =IFERROR(VLOOKUP(C39,路飞话务数据源!D:Q,12,FALSE),0) -> 0 | Q39: =IFERROR(VLOOKUP(C39,路飞话务数据源!D:Q,13,FALSE),0) -> 0 | R39: =IF(OR(TODAY()-E39<=7,F39<5),0,1) -> 0 | S39: =IF(DATEDIF(E39,TODAY(),"M")>=12*3,"3年以上",IF(AND(DATEDIF(E39,TODAY(),"M")>=12*2,DATEDIF(E39,TODAY(),"M")<12*3),"2年-3年",IF(AND(DATEDIF(E39,TODAY(),"M")>=12,DATEDIF(E39,TODAY(),"M")<12*3),"1年-2年",IF(AND(DATEDIF(E39,TODAY(),"M")<12,DATEDIF(E39,TODAY(),"M")>=7),"7月-12月",IF(AND(DATEDIF(E39,TODAY(),"M")<7,DATEDIF(E39,TODAY(),"M")>=3),"4月-6月",IF(DATEDIF(E39,TODAY(),"M")=0,"月内","1-3月")))))) -> 1-3月 | T39: 张日昂 | U39: =SUMIFS(路飞意向数据源!F:F,路飞意向数据源!B:B,A39,路飞意向数据源!C:C,B39,路飞意向数据源!D:D,C39) -> 0
A40: 杭州 | B40: 地推一部 | C40: 杨雅倩 | D40: yangyaqian02 | E40: 2021-03-12 | F40: =IFERROR(VLOOKUP(C40,路飞话务数据源!D:Q,2,FALSE),0) -> 0 | G40: =IFERROR(VLOOKUP(C40,路飞话务数据源!D:Q,3,FALSE),0) -> 0 | H40: =IFERROR(VLOOKUP(C40,路飞话务数据源!D:Q,4,FALSE),0) -> 0 | I40: =IFERROR(VLOOKUP(C40,路飞话务数据源!D:Q,5,FALSE),0) -> 0 | J40: =IFERROR(VLOOKUP(C40,路飞话务数据源!D:Q,6,FALSE),0) -> 0 | K40: =IFERROR(VLOOKUP(C40,路飞话务数据源!D:Q,7,FALSE),0) -> 0 | L40: =IFERROR(VLOOKUP(C40,路飞话务数据源!D:Q,8,FALSE),0) -> 0 | M40: =IFERROR(VLOOKUP(C40,路飞话务数据源!D:Q,9,FALSE),0) -> 0 | N40: =IFERROR(VLOOKUP(C40,路飞话务数据源!D:Q,10,FALSE),0) -> 0 | O40: =IFERROR(VLOOKUP(C40,路飞话务数据源!D:Q,11,FALSE),0) -> 0 | P40: =IFERROR(VLOOKUP(C40,路飞话务数据源!D:Q,12,FALSE),0) -> 0 | Q40: =IFERROR(VLOOKUP(C40,路飞话务数据源!D:Q,13,FALSE),0) -> 0 | R40: =IF(OR(TODAY()-E40<=7,F40<5),0,1) -> 0 | S40: =IF(DATEDIF(E40,TODAY(),"M")>=12*3,"3年以上",IF(AND(DATEDIF(E40,TODAY(),"M")>=12*2,DATEDIF(E40,TODAY(),"M")<12*3),"2年-3年",IF(AND(DATEDIF(E40,TODAY(),"M")>=12,DATEDIF(E40,TODAY(),"M")<12*3),"1年-2年",IF(AND(DATEDIF(E40,TODAY(),"M")<12,DATEDIF(E40,TODAY(),"M")>=7),"7月-12月",IF(AND(DATEDIF(E40,TODAY(),"M")<7,DATEDIF(E40,TODAY(),"M")>=3),"4月-6月",IF(DATEDIF(E40,TODAY(),"M")=0,"月内","1-3月")))))) -> 3年以上 | T40: 张日昂 | U40: =SUMIFS(路飞意向数据源!F:F,路飞意向数据源!B:B,A40,路飞意向数据源!C:C,B40,路飞意向数据源!D:D,C40) -> 0
A41: 杭州 | B41: 新签二部 | C41: 张绍权 | D41: zhangshaoquan01 | E41: 2024-07-01 | F41: =IFERROR(VLOOKUP(C41,路飞话务数据源!D:Q,2,FALSE),0) -> 62 | G41: =IFERROR(VLOOKUP(C41,路飞话务数据源!D:Q,3,FALSE),0) -> 30 | H41: =IFERROR(VLOOKUP(C41,路飞话务数据源!D:Q,4,FALSE),0) -> 0.48387097 | I41: =IFERROR(VLOOKUP(C41,路飞话务数据源!D:Q,5,FALSE),0) -> 10 | J41: =IFERROR(VLOOKUP(C41,路飞话务数据源!D:Q,6,FALSE),0) -> 6 | K41: =IFERROR(VLOOKUP(C41,路飞话务数据源!D:Q,7,FALSE),0) -> 6 | L41: =IFERROR(VLOOKUP(C41,路飞话务数据源!D:Q,8,FALSE),0) -> 0 | M41: =IFERROR(VLOOKUP(C41,路飞话务数据源!D:Q,9,FALSE),0) -> 15.216667 | N41: =IFERROR(VLOOKUP(C41,路飞话务数据源!D:Q,10,FALSE),0) -> 2 | O41: =IFERROR(VLOOKUP(C41,路飞话务数据源!D:Q,11,FALSE),0) -> 0 | P41: =IFERROR(VLOOKUP(C41,路飞话务数据源!D:Q,12,FALSE),0) -> 0 | Q41: =IFERROR(VLOOKUP(C41,路飞话务数据源!D:Q,13,FALSE),0) -> 87 | R41: =IF(OR(TODAY()-E41<=7,F41<5),0,1) -> 1 | S41: =IF(DATEDIF(E41,TODAY(),"M")>=12*3,"3年以上",IF(AND(DATEDIF(E41,TODAY(),"M")>=12*2,DATEDIF(E41,TODAY(),"M")<12*3),"2年-3年",IF(AND(DATEDIF(E41,TODAY(),"M")>=12,DATEDIF(E41,TODAY(),"M")<12*3),"1年-2年",IF(AND(DATEDIF(E41,TODAY(),"M")<12,DATEDIF(E41,TODAY(),"M")>=7),"7月-12月",IF(AND(DATEDIF(E41,TODAY(),"M")<7,DATEDIF(E41,TODAY(),"M")>=3),"4月-6月",IF(DATEDIF(E41,TODAY(),"M")=0,"月内","1-3月")))))) -> 1-3月 | T41: 徐小慧 | U41: =SUMIFS(路飞意向数据源!F:F,路飞意向数据源!B:B,A41,路飞意向数据源!C:C,B41,路飞意向数据源!D:D,C41) -> 3
A42: 杭州 | B42: 新签二部 | C42: 楼鼎元 | D42: loudingyuan | E42: 2024-03-18 | F42: =IFERROR(VLOOKUP(C42,路飞话务数据源!D:Q,2,FALSE),0) -> 127 | G42: =IFERROR(VLOOKUP(C42,路飞话务数据源!D:Q,3,FALSE),0) -> 66 | H42: =IFERROR(VLOOKUP(C42,路飞话务数据源!D:Q,4,FALSE),0) -> 0.51968504 | I42: =IFERROR(VLOOKUP(C42,路飞话务数据源!D:Q,5,FALSE),0) -> 24 | J42: =IFERROR(VLOOKUP(C42,路飞话务数据源!D:Q,6,FALSE),0) -> 19 | K42: =IFERROR(VLOOKUP(C42,路飞话务数据源!D:Q,7,FALSE),0) -> 9 | L42: =IFERROR(VLOOKUP(C42,路飞话务数据源!D:Q,8,FALSE),0) -> 0 | M42: =IFERROR(VLOOKUP(C42,路飞话务数据源!D:Q,9,FALSE),0) -> 36.35 | N42: =IFERROR(VLOOKUP(C42,路飞话务数据源!D:Q,10,FALSE),0) -> 0 | O42: =IFERROR(VLOOKUP(C42,路飞话务数据源!D:Q,11,FALSE),0) -> 0 | P42: =IFERROR(VLOOKUP(C42,路飞话务数据源!D:Q,12,FALSE),0) -> 0 | Q42: =IFERROR(VLOOKUP(C42,路飞话务数据源!D:Q,13,FALSE),0) -> 0 | R42: =IF(OR(TODAY()-E42<=7,F42<5),0,1) -> 1 | S42: =IF(DATEDIF(E42,TODAY(),"M")>=12*3,"3年以上",IF(AND(DATEDIF(E42,TODAY(),"M")>=12*2,DATEDIF(E42,TODAY(),"M")<12*3),"2年-3年",IF(AND(DATEDIF(E42,TODAY(),"M")>=12,DATEDIF(E42,TODAY(),"M")<12*3),"1年-2年",IF(AND(DATEDIF(E42,TODAY(),"M")<12,DATEDIF(E42,TODAY(),"M")>=7),"7月-12月",IF(AND(DATEDIF(E42,TODAY(),"M")<7,DATEDIF(E42,TODAY(),"M")>=3),"4月-6月",IF(DATEDIF(E42,TODAY(),"M")=0,"月内","1-3月")))))) -> 4月-6月 | T42: 徐小慧 | U42: =SUMIFS(路飞意向数据源!F:F,路飞意向数据源!B:B,A42,路飞意向数据源!C:C,B42,路飞意向数据源!D:D,C42) -> 0
A43: 杭州 | B43: 新签二部 | C43: 张成杰 | D43: zhangchengjie01 | E43: 2023-05-06 | F43: =IFERROR(VLOOKUP(C43,路飞话务数据源!D:Q,2,FALSE),0) -> 69 | G43: =IFERROR(VLOOKUP(C43,路飞话务数据源!D:Q,3,FALSE),0) -> 33 | H43: =IFERROR(VLOOKUP(C43,路飞话务数据源!D:Q,4,FALSE),0) -> 0.47826087 | I43: =IFERROR(VLOOKUP(C43,路飞话务数据源!D:Q,5,FALSE),0) -> 17 | J43: =IFERROR(VLOOKUP(C43,路飞话务数据源!D:Q,6,FALSE),0) -> 15 | K43: =IFERROR(VLOOKUP(C43,路飞话务数据源!D:Q,7,FALSE),0) -> 5 | L43: =IFERROR(VLOOKUP(C43,路飞话务数据源!D:Q,8,FALSE),0) -> 1 | M43: =IFERROR(VLOOKUP(C43,路飞话务数据源!D:Q,9,FALSE),0) -> 26.433333 | N43: =IFERROR(VLOOKUP(C43,路飞话务数据源!D:Q,10,FALSE),0) -> 1 | O43: =IFERROR(VLOOKUP(C43,路飞话务数据源!D:Q,11,FALSE),0) -> 1 | P43: =IFERROR(VLOOKUP(C43,路飞话务数据源!D:Q,12,FALSE),0) -> 1 | Q43: =IFERROR(VLOOKUP(C43,路飞话务数据源!D:Q,13,FALSE),0) -> 22 | R43: =IF(OR(TODAY()-E43<=7,F43<5),0,1) -> 1 | S43: =IF(DATEDIF(E43,TODAY(),"M")>=12*3,"3年以上",IF(AND(DATEDIF(E43,TODAY(),"M")>=12*2,DATEDIF(E43,TODAY(),"M")<12*3),"2年-3年",IF(AND(DATEDIF(E43,TODAY(),"M")>=12,DATEDIF(E43,TODAY(),"M")<12*3),"1年-2年",IF(AND(DATEDIF(E43,TODAY(),"M")<12,DATEDIF(E43,TODAY(),"M")>=7),"7月-12月",IF(AND(DATEDIF(E43,TODAY(),"M")<7,DATEDIF(E43,TODAY(),"M")>=3),"4月-6月",IF(DATEDIF(E43,TODAY(),"M")=0,"月内","1-3月")))))) -> 1年-2年 | T43: 徐小慧 | U43: =SUMIFS(路飞意向数据源!F:F,路飞意向数据源!B:B,A43,路飞意向数据源!C:C,B43,路飞意向数据源!D:D,C43) -> 1
A44: 杭州 | B44: 新签二部 | C44: 唐杰伟 | D44: tangjiewei | E44: 2018-07-02 | F44: =IFERROR(VLOOKUP(C44,路飞话务数据源!D:Q,2,FALSE),0) -> 341 | G44: =IFERROR(VLOOKUP(C44,路飞话务数据源!D:Q,3,FALSE),0) -> 146 | H44: =IFERROR(VLOOKUP(C44,路飞话务数据源!D:Q,4,FALSE),0) -> 0.42815249 | I44: =IFERROR(VLOOKUP(C44,路飞话务数据源!D:Q,5,FALSE),0) -> 51 | J44: =IFERROR(VLOOKUP(C44,路飞话务数据源!D:Q,6,FALSE),0) -> 31 | K44: =IFERROR(VLOOKUP(C44,路飞话务数据源!D:Q,7,FALSE),0) -> 19 | L44: =IFERROR(VLOOKUP(C44,路飞话务数据源!D:Q,8,FALSE),0) -> 2 | M44: =IFERROR(VLOOKUP(C44,路飞话务数据源!D:Q,9,FALSE),0) -> 77.766667 | N44: =IFERROR(VLOOKUP(C44,路飞话务数据源!D:Q,10,FALSE),0) -> 0 | O44: =IFERROR(VLOOKUP(C44,路飞话务数据源!D:Q,11,FALSE),0) -> 0 | P44: =IFERROR(VLOOKUP(C44,路飞话务数据源!D:Q,12,FALSE),0) -> 0 | Q44: =IFERROR(VLOOKUP(C44,路飞话务数据源!D:Q,13,FALSE),0) -> 0 | R44: =IF(OR(TODAY()-E44<=7,F44<5),0,1) -> 1 | S44: =IF(DATEDIF(E44,TODAY(),"M")>=12*3,"3年以上",IF(AND(DATEDIF(E44,TODAY(),"M")>=12*2,DATEDIF(E44,TODAY(),"M")<12*3),"2年-3年",IF(AND(DATEDIF(E44,TODAY(),"M")>=12,DATEDIF(E44,TODAY(),"M")<12*3),"1年-2年",IF(AND(DATEDIF(E44,TODAY(),"M")<12,DATEDIF(E44,TODAY(),"M")>=7),"7月-12月",IF(AND(DATEDIF(E44,TODAY(),"M")<7,DATEDIF(E44,TODAY(),"M")>=3),"4月-6月",IF(DATEDIF(E44,TODAY(),"M")=0,"月内","1-3月")))))) -> 3年以上 | T44: 徐小慧 | U44: =SUMIFS(路飞意向数据源!F:F,路飞意向数据源!B:B,A44,路飞意向数据源!C:C,B44,路飞意向数据源!D:D,C44) -> 0
A45: 杭州 | B45: 新签二部 | C45: 吴琳 | D45: wulin04 | E45: 2023-10-09 | F45: =IFERROR(VLOOKUP(C45,路飞话务数据源!D:Q,2,FALSE),0) -> 119 | G45: =IFERROR(VLOOKUP(C45,路飞话务数据源!D:Q,3,FALSE),0) -> 50 | H45: =IFERROR(VLOOKUP(C45,路飞话务数据源!D:Q,4,FALSE),0) -> 0.42016807 | I45: =IFERROR(VLOOKUP(C45,路飞话务数据源!D:Q,5,FALSE),0) -> 27 | J45: =IFERROR(VLOOKUP(C45,路飞话务数据源!D:Q,6,FALSE),0) -> 21 | K45: =IFERROR(VLOOKUP(C45,路飞话务数据源!D:Q,7,FALSE),0) -> 12 | L45: =IFERROR(VLOOKUP(C45,路飞话务数据源!D:Q,8,FALSE),0) -> 2 | M45: =IFERROR(VLOOKUP(C45,路飞话务数据源!D:Q,9,FALSE),0) -> 38.05 | N45: =IFERROR(VLOOKUP(C45,路飞话务数据源!D:Q,10,FALSE),0) -> 0 | O45: =IFERROR(VLOOKUP(C45,路飞话务数据源!D:Q,11,FALSE),0) -> 0 | P45: =IFERROR(VLOOKUP(C45,路飞话务数据源!D:Q,12,FALSE),0) -> 0 | Q45: =IFERROR(VLOOKUP(C45,路飞话务数据源!D:Q,13,FALSE),0) -> 0 | R45: =IF(OR(TODAY()-E45<=7,F45<5),0,1) -> 1 | S45: =IF(DATEDIF(E45,TODAY(),"M")>=12*3,"3年以上",IF(AND(DATEDIF(E45,TODAY(),"M")>=12*2,DATEDIF(E45,TODAY(),"M")<12*3),"2年-3年",IF(AND(DATEDIF(E45,TODAY(),"M")>=12,DATEDIF(E45,TODAY(),"M")<12*3),"1年-2年",IF(AND(DATEDIF(E45,TODAY(),"M")<12,DATEDIF(E45,TODAY(),"M")>=7),"7月-12月",IF(AND(DATEDIF(E45,TODAY(),"M")<7,DATEDIF(E45,TODAY(),"M")>=3),"4月-6月",IF(DATEDIF(E45,TODAY(),"M")=0,"月内","1-3月")))))) -> 7月-12月 | T45: 徐小慧 | U45: =SUMIFS(路飞意向数据源!F:F,路飞意向数据源!B:B,A45,路飞意向数据源!C:C,B45,路飞意向数据源!D:D,C45) -> 0
A46: 杭州 | B46: 新签二部 | C46: 杨蓓蕾 | D46: yangbeilei | E46: 2024-08-16 | F46: =IFERROR(VLOOKUP(C46,路飞话务数据源!D:Q,2,FALSE),0) -> 195 | G46: =IFERROR(VLOOKUP(C46,路飞话务数据源!D:Q,3,FALSE),0) -> 99 | H46: =IFERROR(VLOOKUP(C46,路飞话务数据源!D:Q,4,FALSE),0) -> 0.50769231 | I46: =IFERROR(VLOOKUP(C46,路飞话务数据源!D:Q,5,FALSE),0) -> 29 | J46: =IFERROR(VLOOKUP(C46,路飞话务数据源!D:Q,6,FALSE),0) -> 18 | K46: =IFERROR(VLOOKUP(C46,路飞话务数据源!D:Q,7,FALSE),0) -> 12 | L46: =IFERROR(VLOOKUP(C46,路飞话务数据源!D:Q,8,FALSE),0) -> 0 | M46: =IFERROR(VLOOKUP(C46,路飞话务数据源!D:Q,9,FALSE),0) -> 47.433333 | N46: =IFERROR(VLOOKUP(C46,路飞话务数据源!D:Q,10,FALSE),0) -> 0 | O46: =IFERROR(VLOOKUP(C46,路飞话务数据源!D:Q,11,FALSE),0) -> 0 | P46: =IFERROR(VLOOKUP(C46,路飞话务数据源!D:Q,12,FALSE),0) -> 0 | Q46: =IFERROR(VLOOKUP(C46,路飞话务数据源!D:Q,13,FALSE),0) -> 0 | R46: 0 | S46: =IF(DATEDIF(E46,TODAY(),"M")>=12*3,"3年以上",IF(AND(DATEDIF(E46,TODAY(),"M")>=12*2,DATEDIF(E46,TODAY(),"M")<12*3),"2年-3年",IF(AND(DATEDIF(E46,TODAY(),"M")>=12,DATEDIF(E46,TODAY(),"M")<12*3),"1年-2年",IF(AND(DATEDIF(E46,TODAY(),"M")<12,DATEDIF(E46,TODAY(),"M")>=7),"7月-12月",IF(AND(DATEDIF(E46,TODAY(),"M")<7,DATEDIF(E46,TODAY(),"M")>=3),"4月-6月",IF(DATEDIF(E46,TODAY(),"M")=0,"月内","1-3月")))))) -> 月内 | T46: 徐小慧 | U46: =SUMIFS(路飞意向数据源!F:F,路飞意向数据源!B:B,A46,路飞意向数据源!C:C,B46,路飞意向数据源!D:D,C46) -> 0
A47: 杭州 | B47: 新签二部 | C47: 朱青青 | D47: zhuqingqing | E47: 2024-08-05 | F47: =IFERROR(VLOOKUP(C47,路飞话务数据源!D:Q,2,FALSE),0) -> 181 | G47: =IFERROR(VLOOKUP(C47,路飞话务数据源!D:Q,3,FALSE),0) -> 112 | H47: =IFERROR(VLOOKUP(C47,路飞话务数据源!D:Q,4,FALSE),0) -> 0.61878453 | I47: =IFERROR(VLOOKUP(C47,路飞话务数据源!D:Q,5,FALSE),0) -> 54 | J47: =IFERROR(VLOOKUP(C47,路飞话务数据源!D:Q,6,FALSE),0) -> 35 | K47: =IFERROR(VLOOKUP(C47,路飞话务数据源!D:Q,7,FALSE),0) -> 24 | L47: =IFERROR(VLOOKUP(C47,路飞话务数据源!D:Q,8,FALSE),0) -> 2 | M47: =IFERROR(VLOOKUP(C47,路飞话务数据源!D:Q,9,FALSE),0) -> 82.7 | N47: =IFERROR(VLOOKUP(C47,路飞话务数据源!D:Q,10,FALSE),0) -> 0 | O47: =IFERROR(VLOOKUP(C47,路飞话务数据源!D:Q,11,FALSE),0) -> 0 | P47: =IFERROR(VLOOKUP(C47,路飞话务数据源!D:Q,12,FALSE),0) -> 0 | Q47: =IFERROR(VLOOKUP(C47,路飞话务数据源!D:Q,13,FALSE),0) -> 0 | R47: =IF(OR(TODAY()-E47<=7,F47<5),0,1) -> 1 | S47: =IF(DATEDIF(E47,TODAY(),"M")>=12*3,"3年以上",IF(AND(DATEDIF(E47,TODAY(),"M")>=12*2,DATEDIF(E47,TODAY(),"M")<12*3),"2年-3年",IF(AND(DATEDIF(E47,TODAY(),"M")>=12,DATEDIF(E47,TODAY(),"M")<12*3),"1年-2年",IF(AND(DATEDIF(E47,TODAY(),"M")<12,DATEDIF(E47,TODAY(),"M")>=7),"7月-12月",IF(AND(DATEDIF(E47,TODAY(),"M")<7,DATEDIF(E47,TODAY(),"M")>=3),"4月-6月",IF(DATEDIF(E47,TODAY(),"M")=0,"月内","1-3月")))))) -> 月内 | T47: 徐小慧 | U47: =SUMIFS(路飞意向数据源!F:F,路飞意向数据源!B:B,A47,路飞意向数据源!C:C,B47,路飞意向数据源!D:D,C47) -> 0
A48: 杭州 | B48: 新签二部 | C48: 何文瀚 | D48: hewenhan | E48: 2024-05-27 | F48: =IFERROR(VLOOKUP(C48,路飞话务数据源!D:Q,2,FALSE),0) -> 160 | G48: =IFERROR(VLOOKUP(C48,路飞话务数据源!D:Q,3,FALSE),0) -> 78 | H48: =IFERROR(VLOOKUP(C48,路飞话务数据源!D:Q,4,FALSE),0) -> 0.4875 | I48: =IFERROR(VLOOKUP(C48,路飞话务数据源!D:Q,5,FALSE),0) -> 37 | J48: =IFERROR(VLOOKUP(C48,路飞话务数据源!D:Q,6,FALSE),0) -> 24 | K48: =IFERROR(VLOOKUP(C48,路飞话务数据源!D:Q,7,FALSE),0) -> 13 | L48: =IFERROR(VLOOKUP(C48,路飞话务数据源!D:Q,8,FALSE),0) -> 2 | M48: =IFERROR(VLOOKUP(C48,路飞话务数据源!D:Q,9,FALSE),0) -> 75.05 | N48: =IFERROR(VLOOKUP(C48,路飞话务数据源!D:Q,10,FALSE),0) -> 0 | O48: =IFERROR(VLOOKUP(C48,路飞话务数据源!D:Q,11,FALSE),0) -> 0 | P48: =IFERROR(VLOOKUP(C48,路飞话务数据源!D:Q,12,FALSE),0) -> 0 | Q48: =IFERROR(VLOOKUP(C48,路飞话务数据源!D:Q,13,FALSE),0) -> 0 | R48: =IF(OR(TODAY()-E48<=7,F48<5),0,1) -> 1 | S48: =IF(DATEDIF(E48,TODAY(),"M")>=12*3,"3年以上",IF(AND(DATEDIF(E48,TODAY(),"M")>=12*2,DATEDIF(E48,TODAY(),"M")<12*3),"2年-3年",IF(AND(DATEDIF(E48,TODAY(),"M")>=12,DATEDIF(E48,TODAY(),"M")<12*3),"1年-2年",IF(AND(DATEDIF(E48,TODAY(),"M")<12,DATEDIF(E48,TODAY(),"M")>=7),"7月-12月",IF(AND(DATEDIF(E48,TODAY(),"M")<7,DATEDIF(E48,TODAY(),"M")>=3),"4月-6月",IF(DATEDIF(E48,TODAY(),"M")=0,"月内","1-3月")))))) -> 4月-6月 | T48: 徐小慧 | U48: =SUMIFS(路飞意向数据源!F:F,路飞意向数据源!B:B,A48,路飞意向数据源!C:C,B48,路飞意向数据源!D:D,C48) -> 0
A49: 杭州 | B49: 新签二部 | C49: 胡凯伦 | D49: hukailun | E49: 2024-05-27 | F49: =IFERROR(VLOOKUP(C49,路飞话务数据源!D:Q,2,FALSE),0) -> 192 | G49: =IFERROR(VLOOKUP(C49,路飞话务数据源!D:Q,3,FALSE),0) -> 99 | H49: =IFERROR(VLOOKUP(C49,路飞话务数据源!D:Q,4,FALSE),0) -> 0.515625 | I49: =IFERROR(VLOOKUP(C49,路飞话务数据源!D:Q,5,FALSE),0) -> 26 | J49: =IFERROR(VLOOKUP(C49,路飞话务数据源!D:Q,6,FALSE),0) -> 13 | K49: =IFERROR(VLOOKUP(C49,路飞话务数据源!D:Q,7,FALSE),0) -> 5 | L49: =IFERROR(VLOOKUP(C49,路飞话务数据源!D:Q,8,FALSE),0) -> 1 | M49: =IFERROR(VLOOKUP(C49,路飞话务数据源!D:Q,9,FALSE),0) -> 45.716667 | N49: =IFERROR(VLOOKUP(C49,路飞话务数据源!D:Q,10,FALSE),0) -> 0 | O49: =IFERROR(VLOOKUP(C49,路飞话务数据源!D:Q,11,FALSE),0) -> 0 | P49: =IFERROR(VLOOKUP(C49,路飞话务数据源!D:Q,12,FALSE),0) -> 0 | Q49: =IFERROR(VLOOKUP(C49,路飞话务数据源!D:Q,13,FALSE),0) -> 0 | R49: =IF(OR(TODAY()-E49<=7,F49<5),0,1) -> 1 | S49: =IF(DATEDIF(E49,TODAY(),"M")>=12*3,"3年以上",IF(AND(DATEDIF(E49,TODAY(),"M")>=12*2,DATEDIF(E49,TODAY(),"M")<12*3),"2年-3年",IF(AND(DATEDIF(E49,TODAY(),"M")>=12,DATEDIF(E49,TODAY(),"M")<12*3),"1年-2年",IF(AND(DATEDIF(E49,TODAY(),"M")<12,DATEDIF(E49,TODAY(),"M")>=7),"7月-12月",IF(AND(DATEDIF(E49,TODAY(),"M")<7,DATEDIF(E49,TODAY(),"M")>=3),"4月-6月",IF(DATEDIF(E49,TODAY(),"M")=0,"月内","1-3月")))))) -> 4月-6月 | T49: 徐小慧 | U49: =SUMIFS(路飞意向数据源!F:F,路飞意向数据源!B:B,A49,路飞意向数据源!C:C,B49,路飞意向数据源!D:D,C49) -> 0
A50: 青岛 | B50: 地推一部 | C50: 魏佳昊 | D50: weijiahao | E50: 2024-07-01 | F50: =IFERROR(VLOOKUP(C50,路飞话务数据源!D:Q,2,FALSE),0) -> 32 | G50: =IFERROR(VLOOKUP(C50,路飞话务数据源!D:Q,3,FALSE),0) -> 19 | H50: =IFERROR(VLOOKUP(C50,路飞话务数据源!D:Q,4,FALSE),0) -> 0.59375 | I50: =IFERROR(VLOOKUP(C50,路飞话务数据源!D:Q,5,FALSE),0) -> 7 | J50: =IFERROR(VLOOKUP(C50,路飞话务数据源!D:Q,6,FALSE),0) -> 4 | K50: =IFERROR(VLOOKUP(C50,路飞话务数据源!D:Q,7,FALSE),0) -> 3 | L50: =IFERROR(VLOOKUP(C50,路飞话务数据源!D:Q,8,FALSE),0) -> 0 | M50: =IFERROR(VLOOKUP(C50,路飞话务数据源!D:Q,9,FALSE),0) -> 10.783333 | N50: =IFERROR(VLOOKUP(C50,路飞话务数据源!D:Q,10,FALSE),0) -> 0 | O50: =IFERROR(VLOOKUP(C50,路飞话务数据源!D:Q,11,FALSE),0) -> 0 | P50: =IFERROR(VLOOKUP(C50,路飞话务数据源!D:Q,12,FALSE),0) -> 0 | Q50: =IFERROR(VLOOKUP(C50,路飞话务数据源!D:Q,13,FALSE),0) -> 0 | R50: =IF(OR(TODAY()-E50<=7,F50<5),0,1) -> 1 | S50: =IF(DATEDIF(E50,TODAY(),"M")>=12*3,"3年以上",IF(AND(DATEDIF(E50,TODAY(),"M")>=12*2,DATEDIF(E50,TODAY(),"M")<12*3),"2年-3年",IF(AND(DATEDIF(E50,TODAY(),"M")>=12,DATEDIF(E50,TODAY(),"M")<12*3),"1年-2年",IF(AND(DATEDIF(E50,TODAY(),"M")<12,DATEDIF(E50,TODAY(),"M")>=7),"7月-12月",IF(AND(DATEDIF(E50,TODAY(),"M")<7,DATEDIF(E50,TODAY(),"M")>=3),"4月-6月",IF(DATEDIF(E50,TODAY(),"M")=0,"月内","1-3月")))))) -> 1-3月 | T50: 庄晨晨 | U50: =SUMIFS(路飞意向数据源!F:F,路飞意向数据源!B:B,A50,路飞意向数据源!C:C,B50,路飞意向数据源!D:D,C50) -> 0
A51: 青岛 | B51: 地推一部 | C51: 李可 | D51: like25 | E51: 2024-03-25 | F51: =IFERROR(VLOOKUP(C51,路飞话务数据源!D:Q,2,FALSE),0) -> 0 | G51: =IFERROR(VLOOKUP(C51,路飞话务数据源!D:Q,3,FALSE),0) -> 0 | H51: =IFERROR(VLOOKUP(C51,路飞话务数据源!D:Q,4,FALSE),0) -> 0 | I51: =IFERROR(VLOOKUP(C51,路飞话务数据源!D:Q,5,FALSE),0) -> 0 | J51: =IFERROR(VLOOKUP(C51,路飞话务数据源!D:Q,6,FALSE),0) -> 0 | K51: =IFERROR(VLOOKUP(C51,路飞话务数据源!D:Q,7,FALSE),0) -> 0 | L51: =IFERROR(VLOOKUP(C51,路飞话务数据源!D:Q,8,FALSE),0) -> 0 | M51: =IFERROR(VLOOKUP(C51,路飞话务数据源!D:Q,9,FALSE),0) -> 0 | N51: =IFERROR(VLOOKUP(C51,路飞话务数据源!D:Q,10,FALSE),0) -> 0 | O51: =IFERROR(VLOOKUP(C51,路飞话务数据源!D:Q,11,FALSE),0) -> 0 | P51: =IFERROR(VLOOKUP(C51,路飞话务数据源!D:Q,12,FALSE),0) -> 0 | Q51: =IFERROR(VLOOKUP(C51,路飞话务数据源!D:Q,13,FALSE),0) -> 0 | R51: =IF(OR(TODAY()-E51<=7,F51<5),0,1) -> 0 | S51: =IF(DATEDIF(E51,TODAY(),"M")>=12*3,"3年以上",IF(AND(DATEDIF(E51,TODAY(),"M")>=12*2,DATEDIF(E51,TODAY(),"M")<12*3),"2年-3年",IF(AND(DATEDIF(E51,TODAY(),"M")>=12,DATEDIF(E51,TODAY(),"M")<12*3),"1年-2年",IF(AND(DATEDIF(E51,TODAY(),"M")<12,DATEDIF(E51,TODAY(),"M")>=7),"7月-12月",IF(AND(DATEDIF(E51,TODAY(),"M")<7,DATEDIF(E51,TODAY(),"M")>=3),"4月-6月",IF(DATEDIF(E51,TODAY(),"M")=0,"月内","1-3月")))))) -> 4月-6月 | T51: 庄晨晨 | U51: =SUMIFS(路飞意向数据源!F:F,路飞意向数据源!B:B,A51,路飞意向数据源!C:C,B51,路飞意向数据源!D:D,C51) -> 0
A52: 青岛 | B52: 地推一部 | C52: 李明 | D52: liming58 | E52: 2024-04-18 | F52: =IFERROR(VLOOKUP(C52,路飞话务数据源!D:Q,2,FALSE),0) -> 4 | G52: =IFERROR(VLOOKUP(C52,路飞话务数据源!D:Q,3,FALSE),0) -> 2 | H52: =IFERROR(VLOOKUP(C52,路飞话务数据源!D:Q,4,FALSE),0) -> 0.5 | I52: =IFERROR(VLOOKUP(C52,路飞话务数据源!D:Q,5,FALSE),0) -> 1 | J52: =IFERROR(VLOOKUP(C52,路飞话务数据源!D:Q,6,FALSE),0) -> 0 | K52: =IFERROR(VLOOKUP(C52,路飞话务数据源!D:Q,7,FALSE),0) -> 0 | L52: =IFERROR(VLOOKUP(C52,路飞话务数据源!D:Q,8,FALSE),0) -> 0 | M52: =IFERROR(VLOOKUP(C52,路飞话务数据源!D:Q,9,FALSE),0) -> 0.65 | N52: =IFERROR(VLOOKUP(C52,路飞话务数据源!D:Q,10,FALSE),0) -> 0 | O52: =IFERROR(VLOOKUP(C52,路飞话务数据源!D:Q,11,FALSE),0) -> 0 | P52: =IFERROR(VLOOKUP(C52,路飞话务数据源!D:Q,12,FALSE),0) -> 0 | Q52: =IFERROR(VLOOKUP(C52,路飞话务数据源!D:Q,13,FALSE),0) -> 0 | R52: =IF(OR(TODAY()-E52<=7,F52<5),0,1) -> 0 | S52: =IF(DATEDIF(E52,TODAY(),"M")>=12*3,"3年以上",IF(AND(DATEDIF(E52,TODAY(),"M")>=12*2,DATEDIF(E52,TODAY(),"M")<12*3),"2年-3年",IF(AND(DATEDIF(E52,TODAY(),"M")>=12,DATEDIF(E52,TODAY(),"M")<12*3),"1年-2年",IF(AND(DATEDIF(E52,TODAY(),"M")<12,DATEDIF(E52,TODAY(),"M")>=7),"7月-12月",IF(AND(DATEDIF(E52,TODAY(),"M")<7,DATEDIF(E52,TODAY(),"M")>=3),"4月-6月",IF(DATEDIF(E52,TODAY(),"M")=0,"月内","1-3月")))))) -> 4月-6月 | T52: 庄晨晨 | U52: =SUMIFS(路飞意向数据源!F:F,路飞意向数据源!B:B,A52,路飞意向数据源!C:C,B52,路飞意向数据源!D:D,C52) -> 0
A53: 青岛 | B53: 地推一部 | C53: 于佳林 | D53: yujialin01 | E53: 2024-06-12 | F53: =IFERROR(VLOOKUP(C53,路飞话务数据源!D:Q,2,FALSE),0) -> 0 | G53: =IFERROR(VLOOKUP(C53,路飞话务数据源!D:Q,3,FALSE),0) -> 0 | H53: =IFERROR(VLOOKUP(C53,路飞话务数据源!D:Q,4,FALSE),0) -> 0 | I53: =IFERROR(VLOOKUP(C53,路飞话务数据源!D:Q,5,FALSE),0) -> 0 | J53: =IFERROR(VLOOKUP(C53,路飞话务数据源!D:Q,6,FALSE),0) -> 0 | K53: =IFERROR(VLOOKUP(C53,路飞话务数据源!D:Q,7,FALSE),0) -> 0 | L53: =IFERROR(VLOOKUP(C53,路飞话务数据源!D:Q,8,FALSE),0) -> 0 | M53: =IFERROR(VLOOKUP(C53,路飞话务数据源!D:Q,9,FALSE),0) -> 0 | N53: =IFERROR(VLOOKUP(C53,路飞话务数据源!D:Q,10,FALSE),0) -> 0 | O53: =IFERROR(VLOOKUP(C53,路飞话务数据源!D:Q,11,FALSE),0) -> 0 | P53: =IFERROR(VLOOKUP(C53,路飞话务数据源!D:Q,12,FALSE),0) -> 0 | Q53: =IFERROR(VLOOKUP(C53,路飞话务数据源!D:Q,13,FALSE),0) -> 0 | R53: =IF(OR(TODAY()-E53<=7,F53<5),0,1) -> 0 | S53: =IF(DATEDIF(E53,TODAY(),"M")>=12*3,"3年以上",IF(AND(DATEDIF(E53,TODAY(),"M")>=12*2,DATEDIF(E53,TODAY(),"M")<12*3),"2年-3年",IF(AND(DATEDIF(E53,TODAY(),"M")>=12,DATEDIF(E53,TODAY(),"M")<12*3),"1年-2年",IF(AND(DATEDIF(E53,TODAY(),"M")<12,DATEDIF(E53,TODAY(),"M")>=7),"7月-12月",IF(AND(DATEDIF(E53,TODAY(),"M")<7,DATEDIF(E53,TODAY(),"M")>=3),"4月-6月",IF(DATEDIF(E53,TODAY(),"M")=0,"月内","1-3月")))))) -> 1-3月 | T53: 庄晨晨 | U53: =SUMIFS(路飞意向数据源!F:F,路飞意向数据源!B:B,A53,路飞意向数据源!C:C,B53,路飞意向数据源!D:D,C53) -> 0
A54: 青岛 | B54: 地推一部 | C54: 杨盛喆 | D54: yangshengzhe02 | E54: 2024-07-01 | F54: =IFERROR(VLOOKUP(C54,路飞话务数据源!D:Q,2,FALSE),0) -> 0 | G54: =IFERROR(VLOOKUP(C54,路飞话务数据源!D:Q,3,FALSE),0) -> 0 | H54: =IFERROR(VLOOKUP(C54,路飞话务数据源!D:Q,4,FALSE),0) -> 0 | I54: =IFERROR(VLOOKUP(C54,路飞话务数据源!D:Q,5,FALSE),0) -> 0 | J54: =IFERROR(VLOOKUP(C54,路飞话务数据源!D:Q,6,FALSE),0) -> 0 | K54: =IFERROR(VLOOKUP(C54,路飞话务数据源!D:Q,7,FALSE),0) -> 0 | L54: =IFERROR(VLOOKUP(C54,路飞话务数据源!D:Q,8,FALSE),0) -> 0 | M54: =IFERROR(VLOOKUP(C54,路飞话务数据源!D:Q,9,FALSE),0) -> 0 | N54: =IFERROR(VLOOKUP(C54,路飞话务数据源!D:Q,10,FALSE),0) -> 0 | O54: =IFERROR(VLOOKUP(C54,路飞话务数据源!D:Q,11,FALSE),0) -> 0 | P54: =IFERROR(VLOOKUP(C54,路飞话务数据源!D:Q,12,FALSE),0) -> 0 | Q54: =IFERROR(VLOOKUP(C54,路飞话务数据源!D:Q,13,FALSE),0) -> 0 | R54: =IF(OR(TODAY()-E54<=7,F54<5),0,1) -> 0 | S54: =IF(DATEDIF(E54,TODAY(),"M")>=12*3,"3年以上",IF(AND(DATEDIF(E54,TODAY(),"M")>=12*2,DATEDIF(E54,TODAY(),"M")<12*3),"2年-3年",IF(AND(DATEDIF(E54,TODAY(),"M")>=12,DATEDIF(E54,TODAY(),"M")<12*3),"1年-2年",IF(AND(DATEDIF(E54,TODAY(),"M")<12,DATEDIF(E54,TODAY(),"M")>=7),"7月-12月",IF(AND(DATEDIF(E54,TODAY(),"M")<7,DATEDIF(E54,TODAY(),"M")>=3),"4月-6月",IF(DATEDIF(E54,TODAY(),"M")=0,"月内","1-3月")))))) -> 1-3月 | T54: 庄晨晨 | U54: =SUMIFS(路飞意向数据源!F:F,路飞意向数据源!B:B,A54,路飞意向数据源!C:C,B54,路飞意向数据源!D:D,C54) -> 0
A55: 青岛 | B55: 地推一部 | C55: 张鸿政 | D55: zhanghongzheng | E55: 2024-07-02 | F55: =IFERROR(VLOOKUP(C55,路飞话务数据源!D:Q,2,FALSE),0) -> 15 | G55: =IFERROR(VLOOKUP(C55,路飞话务数据源!D:Q,3,FALSE),0) -> 8 | H55: =IFERROR(VLOOKUP(C55,路飞话务数据源!D:Q,4,FALSE),0) -> 0.53333333 | I55: =IFERROR(VLOOKUP(C55,路飞话务数据源!D:Q,5,FALSE),0) -> 0 | J55: =IFERROR(VLOOKUP(C55,路飞话务数据源!D:Q,6,FALSE),0) -> 0 | K55: =IFERROR(VLOOKUP(C55,路飞话务数据源!D:Q,7,FALSE),0) -> 0 | L55: =IFERROR(VLOOKUP(C55,路飞话务数据源!D:Q,8,FALSE),0) -> 0 | M55: =IFERROR(VLOOKUP(C55,路飞话务数据源!D:Q,9,FALSE),0) -> 2.0166667 | N55: =IFERROR(VLOOKUP(C55,路飞话务数据源!D:Q,10,FALSE),0) -> 0 | O55: =IFERROR(VLOOKUP(C55,路飞话务数据源!D:Q,11,FALSE),0) -> 0 | P55: =IFERROR(VLOOKUP(C55,路飞话务数据源!D:Q,12,FALSE),0) -> 0 | Q55: =IFERROR(VLOOKUP(C55,路飞话务数据源!D:Q,13,FALSE),0) -> 0 | R55: =IF(OR(TODAY()-E55<=7,F55<5),0,1) -> 1 | S55: =IF(DATEDIF(E55,TODAY(),"M")>=12*3,"3年以上",IF(AND(DATEDIF(E55,TODAY(),"M")>=12*2,DATEDIF(E55,TODAY(),"M")<12*3),"2年-3年",IF(AND(DATEDIF(E55,TODAY(),"M")>=12,DATEDIF(E55,TODAY(),"M")<12*3),"1年-2年",IF(AND(DATEDIF(E55,TODAY(),"M")<12,DATEDIF(E55,TODAY(),"M")>=7),"7月-12月",IF(AND(DATEDIF(E55,TODAY(),"M")<7,DATEDIF(E55,TODAY(),"M")>=3),"4月-6月",IF(DATEDIF(E55,TODAY(),"M")=0,"月内","1-3月")))))) -> 1-3月 | T55: 庄晨晨 | U55: =SUMIFS(路飞意向数据源!F:F,路飞意向数据源!B:B,A55,路飞意向数据源!C:C,B55,路飞意向数据源!D:D,C55) -> 0
A56: 青岛 | B56: 地推一部 | C56: 谭庆宇 | D56: tanqingyu | E56: 2024-07-08 | F56: =IFERROR(VLOOKUP(C56,路飞话务数据源!D:Q,2,FALSE),0) -> 0 | G56: =IFERROR(VLOOKUP(C56,路飞话务数据源!D:Q,3,FALSE),0) -> 0 | H56: =IFERROR(VLOOKUP(C56,路飞话务数据源!D:Q,4,FALSE),0) -> 0 | I56: =IFERROR(VLOOKUP(C56,路飞话务数据源!D:Q,5,FALSE),0) -> 0 | J56: =IFERROR(VLOOKUP(C56,路飞话务数据源!D:Q,6,FALSE),0) -> 0 | K56: =IFERROR(VLOOKUP(C56,路飞话务数据源!D:Q,7,FALSE),0) -> 0 | L56: =IFERROR(VLOOKUP(C56,路飞话务数据源!D:Q,8,FALSE),0) -> 0 | M56: =IFERROR(VLOOKUP(C56,路飞话务数据源!D:Q,9,FALSE),0) -> 0 | N56: =IFERROR(VLOOKUP(C56,路飞话务数据源!D:Q,10,FALSE),0) -> 0 | O56: =IFERROR(VLOOKUP(C56,路飞话务数据源!D:Q,11,FALSE),0) -> 0 | P56: =IFERROR(VLOOKUP(C56,路飞话务数据源!D:Q,12,FALSE),0) -> 0 | Q56: =IFERROR(VLOOKUP(C56,路飞话务数据源!D:Q,13,FALSE),0) -> 0 | R56: =IF(OR(TODAY()-E56<=7,F56<5),0,1) -> 0 | S56: =IF(DATEDIF(E56,TODAY(),"M")>=12*3,"3年以上",IF(AND(DATEDIF(E56,TODAY(),"M")>=12*2,DATEDIF(E56,TODAY(),"M")<12*3),"2年-3年",IF(AND(DATEDIF(E56,TODAY(),"M")>=12,DATEDIF(E56,TODAY(),"M")<12*3),"1年-2年",IF(AND(DATEDIF(E56,TODAY(),"M")<12,DATEDIF(E56,TODAY(),"M")>=7),"7月-12月",IF(AND(DATEDIF(E56,TODAY(),"M")<7,DATEDIF(E56,TODAY(),"M")>=3),"4月-6月",IF(DATEDIF(E56,TODAY(),"M")=0,"月内","1-3月")))))) -> 1-3月 | T56: 庄晨晨 | U56: =SUMIFS(路飞意向数据源!F:F,路飞意向数据源!B:B,A56,路飞意向数据源!C:C,B56,路飞意向数据源!D:D,C56) -> 0
...

Sheet 路飞话务数据源
A1: 大区 | B1: 城市 | C1: 部门 | D1: 销售姓名 | E1: 当日呼出电话数 | F1: 当日接通电话数 | G1: 接通率 | H1: 当日30s电话数 | I1: 当日45s电话数 | J1: 当日60s电话数 | K1: 当日180s电话数 | L1: 当日累计接通时长(分钟) | M1: 当日外访客户数 | N1: 当日外访签单客户数 | O1: 当日外访签单率 | P1: 当日总外访时长（分钟）
A2: 华东区 | B2: 青岛 | C2: 通用行业一部 | D2: 朱琳琳 | E2: 1 | F2: 1 | G2: 1 | H2: 0 | I2: 0 | J2: 0 | K2: 0 | L2: 0.23333333
A3: 华东区 | B3: 青岛 | C3: 物流行业一部 | D3: 徐浩栋 | E3: 1 | F3: 0 | G3: 0 | H3: 0 | I3: 0 | J3: 0 | K3: 0 | L3: 0
A4: 华东区 | B4: 青岛 | C4: 物流行业一部 | D4: 胡凡迪 | E4: 32 | F4: 10 | G4: 0.3125 | H4: 3 | I4: 1 | J4: 0 | K4: 0 | L4: 3.8
A5: 华东区 | B5: 青岛 | C5: 新签四部 | D5: 尹丽丽 | E5: 242 | F5: 102 | G5: 0.4214876 | H5: 35 | I5: 22 | J5: 14 | K5: 3 | L5: 63.383333
A6: 华东区 | B6: 青岛 | C6: 新签四部 | D6: 肖冠迪 | E6: 256 | F6: 111 | G6: 0.43359375 | H6: 11 | I6: 7 | J6: 4 | K6: 0 | L6: 37.166667
A7: 华东区 | B7: 青岛 | C7: 新签四部 | D7: 曲世龙 | E7: 108 | F7: 54 | G7: 0.5 | H7: 21 | I7: 18 | J7: 12 | K7: 2 | L7: 41.766667 | M7: 1 | N7: 1 | O7: 1 | P7: 91
A8: 华东区 | B8: 青岛 | C8: 新签四部 | D8: 郭槟恺 | E8: 155 | F8: 63 | G8: 0.40645161 | H8: 16 | I8: 15 | J8: 9 | K8: 1 | L8: 32.85
A9: 华东区 | B9: 青岛 | C9: 新签四部 | D9: 邓琪 | E9: 246 | F9: 100 | G9: 0.40650407 | H9: 20 | I9: 11 | J9: 7 | K9: 0 | L9: 43
A10: 华东区 | B10: 青岛 | C10: 新签四部 | D10: 杜浩天 | E10: 217 | F10: 96 | G10: 0.44239631 | H10: 38 | I10: 29 | J10: 22 | K10: 3 | L10: 64.45
A11: 华东区 | B11: 青岛 | C11: 新签四部 | D11: 张可 | E11: 186 | F11: 70 | G11: 0.37634409 | H11: 30 | I11: 20 | J11: 17 | K11: 4 | L11: 53
A12: 华东区 | B12: 青岛 | C12: 新签二部 | D12: 李先鹏 | E12: 169 | F12: 72 | G12: 0.4260355 | H12: 43 | I12: 35 | J12: 22 | K12: 5 | L12: 82.366667
A13: 华东区 | B13: 青岛 | C13: 新签二部 | D13: 刘旭 | E13: 134 | F13: 68 | G13: 0.50746269 | H13: 35 | I13: 28 | J13: 17 | K13: 2 | L13: 56.366667
A14: 华东区 | B14: 青岛 | C14: 新签二部 | D14: 陈昔金 | E14: 206 | F14: 105 | G14: 0.50970874 | H14: 53 | I14: 39 | J14: 27 | K14: 4 | L14: 87.633333
A15: 华东区 | B15: 青岛 | C15: 新签二部 | D15: 张欣宇 | E15: 255 | F15: 102 | G15: 0.4 | H15: 41 | I15: 32 | J15: 13 | K15: 1 | L15: 56
A16: 华东区 | B16: 青岛 | C16: 新签二部 | D16: 陈景豪 | E16: 120 | F16: 57 | G16: 0.475 | H16: 28 | I16: 16 | J16: 10 | K16: 0 | L16: 34.566667
A17: 华东区 | B17: 青岛 | C17: 新签二部 | D17: 曹可景 | E17: 190 | F17: 99 | G17: 0.52105263 | H17: 25 | I17: 22 | J17: 7 | K17: 0 | L17: 40.55
A18: 华东区 | B18: 青岛 | C18: 新签二部 | D18: 房政杰 | E18: 105 | F18: 48 | G18: 0.45714286 | H18: 18 | I18: 12 | J18: 7 | K18: 1 | L18: 26.816667
A19: 华东区 | B19: 青岛 | C19: 新签二部 | D19: 秦即航 | E19: 177 | F19: 90 | G19: 0.50847458 | H19: 15 | I19: 6 | J19: 3 | K19: 0 | L19: 35.033333
A20: 华东区 | B20: 青岛 | C20: 新签二部 | D20: 练玉洁 | E20: 79 | F20: 28 | G20: 0.35443038 | H20: 15 | I20: 11 | J20: 6 | K20: 1 | L20: 25.9 | M20: 1 | N20: 0 | O20: 0 | P20: 43
A21: 华东区 | B21: 青岛 | C21: 新签三部 | D21: 王连生 | E21: 97 | F21: 39 | G21: 0.40206186 | H21: 13 | I21: 11 | J21: 4 | K21: 1 | L21: 21.083333 | M21: 1 | N21: 0 | O21: 0 | P21: 142
A22: 华东区 | B22: 青岛 | C22: 新签三部 | D22: 刘志昊 | E22: 218 | F22: 106 | G22: 0.48623853 | H22: 33 | I22: 30 | J22: 16 | K22: 4 | L22: 74.383333
A23: 华东区 | B23: 青岛 | C23: 新签三部 | D23: 赵瑞壮 | E23: 1 | F23: 1 | G23: 1 | H23: 0 | I23: 0 | J23: 0 | K23: 0 | L23: 0.21666667
A24: 华东区 | B24: 青岛 | C24: 新签三部 | D24: 金鑫 | E24: 254 | F24: 121 | G24: 0.47637795 | H24: 68 | I24: 52 | J24: 27 | K24: 1 | L24: 90.433333
A25: 华东区 | B25: 青岛 | C25: 新签三部 | D25: 李怀彬 | E25: 170 | F25: 70 | G25: 0.41176471 | H25: 30 | I25: 19 | J25: 10 | K25: 1 | L25: 39.216667
A26: 华东区 | B26: 青岛 | C26: 新签三部 | D26: 任峰江 | E26: 200 | F26: 75 | G26: 0.375 | H26: 31 | I26: 15 | J26: 6 | K26: 0 | L26: 34.8
A27: 华东区 | B27: 青岛 | C27: 新签一部 | D27: 刘钰鑫 | E27: 16 | F27: 9 | G27: 0.5625 | H27: 4 | I27: 4 | J27: 3 | K27: 0 | L27: 7.45 | M27: 1 | N27: 1 | O27: 1 | P27: 176
A28: 华东区 | B28: 青岛 | C28: 新签一部 | D28: 刘艺 | E28: 151 | F28: 64 | G28: 0.42384106 | H28: 27 | I28: 20 | J28: 10 | K28: 4 | L28: 67.533333
A29: 华东区 | B29: 青岛 | C29: 新签一部 | D29: 徐增伟 | E29: 61 | F29: 28 | G29: 0.45901639 | H29: 15 | I29: 12 | J29: 9 | K29: 2 | L29: 30.15
A30: 华东区 | B30: 青岛 | C30: 新签一部 | D30: 刘帅帅 | E30: 28 | F30: 13 | G30: 0.46428571 | H30: 7 | I30: 7 | J30: 4 | K30: 0 | L30: 10.533333
A31: 华东区 | B31: 青岛 | C31: 新签一部 | D31: 董坤 | E31: 95 | F31: 35 | G31: 0.36842105 | H31: 17 | I31: 15 | J31: 12 | K31: 5 | L31: 42.65
A32: 华东区 | B32: 青岛 | C32: 新签一部 | D32: 杨家豪 | E32: 7 | F32: 2 | G32: 0.28571429 | H32: 2 | I32: 2 | J32: 2 | K32: 2 | L32: 11.416667
A33: 华东区 | B33: 青岛 | C33: 新签一部 | D33: 曲赛男 | E33: 98 | F33: 43 | G33: 0.43877551 | H33: 24 | I33: 20 | J33: 13 | K33: 1 | L33: 33.45
A34: 华东区 | B34: 青岛 | C34: 新签一部 | D34: 郑传禹 | E34: 147 | F34: 66 | G34: 0.44897959 | H34: 28 | I34: 24 | J34: 16 | K34: 2 | L34: 52.85
A35: 华东区 | B35: 青岛 | C35: 新签一部 | D35: 杨文斋 | E35: 120 | F35: 52 | G35: 0.43333333 | H35: 28 | I35: 19 | J35: 11 | K35: 2 | L35: 46.466667
A36: 华东区 | B36: 青岛 | C36: 增值一部 | D36: 张学凯 | E36: 30 | F36: 9 | G36: 0.3 | H36: 6 | I36: 6 | J36: 4 | K36: 1 | L36: 11.733333
A37: 华东区 | B37: 青岛 | C37: 增值一部 | D37: 孙俊豪 | E37: 51 | F37: 25 | G37: 0.49019608 | H37: 16 | I37: 12 | J37: 6 | K37: 2 | L37: 26.633333
A38: 华东区 | B38: 青岛 | C38: 增值一部 | D38: 刘心梦 | E38: 6 | F38: 3 | G38: 0.5 | H38: 3 | I38: 3 | J38: 1 | K38: 0 | L38: 3.6333333
A39: 华东区 | B39: 青岛 | C39: 增值一部 | D39: 焦泽 | E39: 8 | F39: 4 | G39: 0.5 | H39: 3 | I39: 1 | J39: 1 | K39: 0 | L39: 3.2
... A52: 华东区 | B52: 苏州 | C52: 物流行业一部 | D52: 卜明阳 | E52: 121 | F52: 53 | G52: 0.43801653 | H52: 23 | I52: 13 | J52: 5 | K52: 0 | L52: 26.633333
...

Sheet 路飞意向数据源
A1: 大区 | B1: 城市 | C1: 部门 | D1: 销售姓名 | E1: 今日提报待审核意向商机数 | F1: 今日提报已审核意向商机数 | G1: 今日提报意向商机金额 | H1: 月度储备金额（含当日） | I1: 月度转化金额 | J1: 月度意向业绩转化率
A2: 华东区 | B2: 青岛 | C2: 新签四部 | D2: 代自豪 | E2: 0 | F2: 0 | G2: 0 | H2: 3000 | I2: 3000 | J2: 1
A3: 华东区 | B3: 青岛 | C3: 通用行业一部 | D3: 蒋清旺 | E3: 0 | F3: 0 | G3: 0 | H3: 0 | I3: 0
A4: 华东区 | B4: 青岛 | C4: 通用行业一部 | D4: 朱琳琳 | E4: 1 | F4: 2 | G4: 6628 | H4: 164842 | I4: 105316 | J4: 0.63889057
A5: 华东区 | B5: 青岛 | C5: 新签二部 | D5: 李先鹏 | E5: 0 | F5: 1 | G5: 3502 | H5: 36742 | I5: 3000 | J5: 0.081650427
A6: 华东区 | B6: 青岛 | C6: 新签一部 | D6: 董坤 | E6: 0 | F6: 2 | G6: 9160 | H6: 49340 | I6: 4030 | J6: 0.081678152
A7: 华东区 | B7: 青岛 | C7: 新签四部 | D7: 邓琪 | E7: 0 | F7: 1 | G7: 3980 | H7: 27960 | I7: 4030 | J7: 0.14413448
A8: 华东区 | B8: 青岛 | C8: 新签一部 | D8: 杨文斋 | E8: 0 | F8: 0 | G8: 0 | H8: 16180 | I8: 4030 | J8: 0.24907293
A9: 华东区 | B9: 青岛 | C9: 新签一部 | D9: 刘艺 | E9: 0 | F9: 0 | G9: 0 | H9: 13740 | I9: 8610 | J9: 0.62663755
A10: 华东区 | B10: 青岛 | C10: 增值一部 | D10: 李雪 | E10: 0 | F10: 0 | G10: 0 | H10: 172316 | I10: 78222 | J10: 0.45394508
A11: 华东区 | B11: 青岛 | C11: 增值一部 | D11: 焦泽 | E11: 0 | F11: 0 | G11: 0 | H11: 17742 | I11: 5000 | J11: 0.28181716
A12: 华东区 | B12: 青岛 | C12: 地推一部 | D12: 于佳林 | E12: 0 | F12: 0 | G12: 0 | H12: 0 | I12: 0
A13: 华东区 | B13: 青岛 | C13: 新签二部 | D13: 陈昔金 | E13: 0 | F13: 0 | G13: 0 | H13: 23402 | I13: 7030 | J13: 0.30040168
A14: 华东区 | B14: 青岛 | C14: 新签一部 | D14: 郑传禹 | E14: 0 | F14: 0 | G14: 0 | H14: 3980 | I14: 0 | J14: 0
A15: 华东区 | B15: 青岛 | C15: 新签三部 | D15: 刘昕宇 | E15: 0 | F15: 0 | G15: 0 | H15: 5660 | I15: 0 | J15: 0
A16: 华东区 | B16: 青岛 | C16: 增值一部 | D16: 刘心梦 | E16: 0 | F16: 0 | G16: 0 | H16: 85280 | I16: 37592 | J16: 0.44080675
A17: 华东区 | B17: 青岛 | C17: 新签三部 | D17: 刘志昊 | E17: 0 | F17: 4 | G17: 20790 | H17: 38390 | I17: 0 | J17: 0
A18: 华东区 | B18: 青岛 | C18: 新签一部 | D18: 徐增伟 | E18: 0 | F18: 0 | G18: 0 | H18: 25280 | I18: 25280 | J18: 1
A19: 华东区 | B19: 青岛 | C19: 新签四部 | D19: 郭槟恺 | E19: 0 | F19: 0 | G19: 0 | H19: 20520 | I19: 16062 | J19: 0.78274854
A20: 华东区 | B20: 青岛 | C20: 新签一部 | D20: 刘帅帅 | E20: 0 | F20: 0 | G20: 0 | H20: 65028 | I20: 15990 | J20: 0.24589408
A21: 华东区 | B21: 青岛 | C21: 增值一部 | D21: 魏广玉 | E21: 0 | F21: 0 | G21: 0 | H21: 64624 | I21: 33864 | J21: 0.52401585
A22: 华东区 | B22: 青岛 | C22: 增值一部 | D22: 史玉蕾 | E22: 0 | F22: 0 | G22: 0 | H22: 5600 | I22: 0 | J22: 0
A23: 华东区 | B23: 青岛 | C23: 新签三部 | D23: 努尔古丽·努尔艾合买提 | E23: 0 | F23: 0 | G23: 0 | H23: 0 | I23: 0
A24: 华东区 | B24: 青岛 | C24: 新签一部 | D24: 曲赛男 | E24: 0 | F24: 1 | G24: 3980 | H24: 8660 | I24: 4680 | J24: 0.5404157
A25: 华东区 | B25: 青岛 | C25: 新签四部 | D25: 杜浩天 | E25: 0 | F25: 1 | G25: 3980 | H25: 78690 | I25: 2580 | J25: 0.032786885
A26: 华东区 | B26: 青岛 | C26: 新签三部 | D26: 任峰江 | E26: 0 | F26: 1 | G26: 3980 | H26: 3980 | I26: 0 | J26: 0
A27: 华东区 | B27: 青岛 | C27: 物流行业一部 | D27: 钱明明 | E27: 0 | F27: 0 | G27: 0 | H27: 580139 | I27: 452475 | J27: 0.77994239
A28: 华东区 | B28: 青岛 | C28: 新签一部 | D28: 闫昭宇 | E28: 0 | F28: 0 | G28: 0 | H28: 0 | I28: 0
A29: 华东区 | B29: 青岛 | C29: 物流行业一部 | D29: 张洁 | E29: 0 | F29: 0 | G29: 0 | H29: 226455 | I29: 54821 | J29: 0.24208342
A30: 华东区 | B30: 青岛 | C30: 新签二部 | D30: 练玉洁 | E30: 0 | F30: 0 | G30: 0 | H30: 18920 | I30: 15062 | J30: 0.79608879
A31: 华东区 | B31: 青岛 | C31: 物流行业一部 | D31: 徐浩栋 | E31: 0 | F31: 1 | G31: 10007 | H31: 166147 | I31: 97500 | J31: 0.58682974
A32: 华东区 | B32: 青岛 | C32: 新签二部 | D32: 刘旭 | E32: 0 | F32: 0 | G32: 0 | H32: 23680 | I32: 4030 | J32: 0.17018581
A33: 华东区 | B33: 青岛 | C33: 新签一部 | D33: 刘钰鑫 | E33: 0 | F33: 1 | G33: 3502 | H33: 9762 | I33: 3000 | J33: 0.30731407
A34: 华东区 | B34: 青岛 | C34: 新签三部 | D34: 李顺欣 | E34: 0 | F34: 0 | G34: 0 | H34: 0 | I34: 0
A35: 华东区 | B35: 青岛 | C35: 新签三部 | D35: 李怀彬 | E35: 0 | F35: 0 | G35: 0 | H35: 57060 | I35: 3000 | J35: 0.052576236
A36: 华东区 | B36: 青岛 | C36: 新签三部 | D36: 王连生 | E36: 0 | F36: 2 | G36: 8010 | H36: 40730 | I36: 22162 | J36: 0.54411981
A37: 华东区 | B37: 青岛 | C37: 增值一部 | D37: 赵旭阳 | E37: 0 | F37: 0 | G37: 0 | H37: 101414 | I37: 66138 | J37: 0.65215848
